Workbook

Sheet Dashboard
A1: Tablero 4DX — GBM Nicaragua
A2: WIG de la compañía: Construir la utilidad neta (NAT) de Nicaragua — $1M en 2027, $2M (7%) en 2028, $2.4M (8%) en 2029
A4: Metas de Utilidad Neta (NAT) 2027 → 2029 (base 2026)
A5: Año | B5: Ingreso | C5: GP % | D5: Meta NAT | E5: NAT % | F5: NAT real | G5: Estado | H5: Ir a pestaña
A6: 2026 (estimado) | B6: 18656000 | C6: 0.144 | D6: 375000 | E6: =D6/B6 -> 0.020100772 | G6: =IF(F6="","—",IF(F6>=D6*0.95,"En meta",IF(F6>=D6*0.8,"Riesgo","Atrasado"))) -> —
A7: 2027 (meta) | B7: 21000000 | C7: 0.16 | D7: 1000000 | E7: =D7/B7 -> 0.047619048 | G7: =IF(F7="","—",IF(F7>=D7*0.95,"En meta",IF(F7>=D7*0.8,"Riesgo","Atrasado"))) -> — | H7: Ver 2027
A8: 2028 (meta) | B8: 28571000 | C8: 0.164 | D8: 2000000 | E8: =D8/B8 -> 0.07000105 | G8: =IF(F8="","—",IF(F8>=D8*0.95,"En meta",IF(F8>=D8*0.8,"Riesgo","Atrasado"))) -> — | H8: Ver 2028
A9: 2029 (meta) | B9: 30571000 | C9: 0.165 | D9: 2445680 | E9: =D9/B9 -> 0.08 | G9: =IF(F9="","—",IF(F9>=D9*0.95,"En meta",IF(F9>=D9*0.8,"Riesgo","Atrasado"))) -> — | H9: Ver 2029
A10: El tope de impuesto mínimo (3% sobre ventas) fija el piso de impuestos; por eso la meta se gana en GP% y en mantener el costo local plano, no solo en crecer ventas.
A12: Cobertura de backlog — GP comprometido vs meta del año
A13: Año | B13: GP meta | C13: GP comprometido | D13: Brecha (falta vender) | E13: % cobertura
A14: 2027 | B14: ='2027'!$B$5 -> 3360000 | C14: ='2027'!$B$6 -> 0 | D14: ='2027'!$B$7 -> 3360000 | E14: ='2027'!$E$6 -> 0
A15: 2028 | B15: ='2028'!$B$5 -> 4685644 | C15: ='2028'!$B$6 -> 0 | D15: ='2028'!$B$7 -> 4685644 | E15: ='2028'!$E$6 -> 0
A16: 2029 | B16: ='2029'!$B$5 -> 5044215 | C16: ='2029'!$B$6 -> 0 | D16: ='2029'!$B$7 -> 5044215 | E16: ='2029'!$E$6 -> 0
A18: Seguimiento mensual NAT — año en curso
A19: Meta anual NAT: | C19: 1000000
A21: Mes | B21: Meta mensual | C21: NAT real | D21: Meta acum. | E21: Real acum. | F21: % avance | G21: Estado
A22: 46388 | B22: =$C$19/12 -> 83333.333 | D22: =SUM($B$22:B22) -> 83333.333 | E22: =SUM($C$22:C22) -> 0 | F22: =IF(COUNT($C$22:C22)=0,"",E22/D22) | G22: =IF(F22="","",IF(F22>=0.95,"En meta",IF(F22>=0.8,"Riesgo","Atrasado")))
A23: 46419 | B23: =$C$19/12 -> 83333.333 | D23: =SUM($B$22:B23) -> 166666.67 | E23: =SUM($C$22:C23) -> 0 | F23: =IF(COUNT($C$22:C23)=0,"",E23/D23) | G23: =IF(F23="","",IF(F23>=0.95,"En meta",IF(F23>=0.8,"Riesgo","Atrasado")))
A24: 46447 | B24: =$C$19/12 -> 83333.333 | D24: =SUM($B$22:B24) -> 250000 | E24: =SUM($C$22:C24) -> 0 | F24: =IF(COUNT($C$22:C24)=0,"",E24/D24) | G24: =IF(F24="","",IF(F24>=0.95,"En meta",IF(F24>=0.8,"Riesgo","Atrasado")))
A25: 46478 | B25: =$C$19/12 -> 83333.333 | D25: =SUM($B$22:B25) -> 333333.33 | E25: =SUM($C$22:C25) -> 0 | F25: =IF(COUNT($C$22:C25)=0,"",E25/D25) | G25: =IF(F25="","",IF(F25>=0.95,"En meta",IF(F25>=0.8,"Riesgo","Atrasado")))
A26: 46508 | B26: =$C$19/12 -> 83333.333 | D26: =SUM($B$22:B26) -> 416666.67 | E26: =SUM($C$22:C26) -> 0 | F26: =IF(COUNT($C$22:C26)=0,"",E26/D26) | G26: =IF(F26="","",IF(F26>=0.95,"En meta",IF(F26>=0.8,"Riesgo","Atrasado")))
A27: 46539 | B27: =$C$19/12 -> 83333.333 | D27: =SUM($B$22:B27) -> 500000 | E27: =SUM($C$22:C27) -> 0 | F27: =IF(COUNT($C$22:C27)=0,"",E27/D27) | G27: =IF(F27="","",IF(F27>=0.95,"En meta",IF(F27>=0.8,"Riesgo","Atrasado")))
A28: 46569 | B28: =$C$19/12 -> 83333.333 | D28: =SUM($B$22:B28) -> 583333.33 | E28: =SUM($C$22:C28) -> 0 | F28: =IF(COUNT($C$22:C28)=0,"",E28/D28) | G28: =IF(F28="","",IF(F28>=0.95,"En meta",IF(F28>=0.8,"Riesgo","Atrasado")))
A29: 46600 | B29: =$C$19/12 -> 83333.333 | D29: =SUM($B$22:B29) -> 666666.67 | E29: =SUM($C$22:C29) -> 0 | F29: =IF(COUNT($C$22:C29)=0,"",E29/D29) | G29: =IF(F29="","",IF(F29>=0.95,"En meta",IF(F29>=0.8,"Riesgo","Atrasado")))
A30: 46631 | B30: =$C$19/12 -> 83333.333 | D30: =SUM($B$22:B30) -> 750000 | E30: =SUM($C$22:C30) -> 0 | F30: =IF(COUNT($C$22:C30)=0,"",E30/D30) | G30: =IF(F30="","",IF(F30>=0.95,"En meta",IF(F30>=0.8,"Riesgo","Atrasado")))
A31: 46661 | B31: =$C$19/12 -> 83333.333 | D31: =SUM($B$22:B31) -> 833333.33 | E31: =SUM($C$22:C31) -> 0 | F31: =IF(COUNT($C$22:C31)=0,"",E31/D31) | G31: =IF(F31="","",IF(F31>=0.95,"En meta",IF(F31>=0.8,"Riesgo","Atrasado")))
A32: 46692 | B32: =$C$19/12 -> 83333.333 | D32: =SUM($B$22:B32) -> 916666.67 | E32: =SUM($C$22:C32) -> 0 | F32: =IF(COUNT($C$22:C32)=0,"",E32/D32) | G32: =IF(F32="","",IF(F32>=0.95,"En meta",IF(F32>=0.8,"Riesgo","Atrasado")))
A33: 46722 | B33: =$C$19/12 -> 83333.333 | D33: =SUM($B$22:B33) -> 1000000 | E33: =SUM($C$22:C33) -> 0 | F33: =IF(COUNT($C$22:C33)=0,"",E33/D33) | G33: =IF(F33="","",IF(F33>=0.95,"En meta",IF(F33>=0.8,"Riesgo","Atrasado")))
A35: WIGs de soporte — estado al último dato ingresado
A36: # | B36: WIG de soporte | C36: Dueño | D36: Equipo | E36: Meta | F36: Último real | G36: Estado | H36: Ir a pestaña
A37: 1 | B37: Incrementar el Parque de Smart User en 500 equipos en el 2026 | C37: ='1. Smart User 500'!$B$4 -> Por asignar | D37: Pre-Sales, Del - DEX | E37: ='1. Smart User 500'!$B$5 -> 500 | F37: =IFERROR(LOOKUP(2,1/('1. Smart User 500'!$D$11:$D$39<>""),'1. Smart User 500'!$D$11:$D$39),"Sin datos") -> Sin datos | G37: =IFERROR(LOOKUP(2,1/('1. Smart User 500'!$D$11:$D$39<>""),'1. Smart User 500'!$H$11:$H$39),"Sin datos") -> Sin datos | H37: 1. Smart User 500
A38: 2 | B38: Lograr un Monthly Value de $X en advisory en el primer trimestre de 2027 | C38: ='2. MV Advisory'!$B$4 -> Por asignar | D38: Ventas, Customer Success, Pre-Sales, Del - TSS | E38: ='2. MV Advisory'!$B$5 -> 10000 | F38: =IFERROR(LOOKUP(2,1/('2. MV Advisory'!$D$11:$D$52<>""),'2. MV Advisory'!$D$11:$D$52),"Sin datos") -> Sin datos | G38: =IFERROR(LOOKUP(2,1/('2. MV Advisory'!$D$11:$D$52<>""),'2. MV Advisory'!$H$11:$H$52),"Sin datos") -> Sin datos | H38: 2. MV Advisory
A39: 3 | B39: Reconocer 10 negocios mayores a $30K de GP en el 2027 | C39: ='3. Negocios +30K GP'!$B$4 -> Por asignar | D39: Ventas, Pre-Sales | E39: ='3. Negocios +30K GP'!$B$5 -> 10 | F39: =IFERROR(LOOKUP(2,1/('3. Negocios +30K GP'!$D$11:$D$91<>""),'3. Negocios +30K GP'!$D$11:$D$91),"Sin datos") -> Sin datos | G39: =IFERROR(LOOKUP(2,1/('3. Negocios +30K GP'!$D$11:$D$91<>""),'3. Negocios +30K GP'!$H$11:$H$91),"Sin datos") -> Sin datos | H39: 3. Negocios +30K GP
A40: 4 | B40: Cumplir el 100% de entregas y colocaciones en tiempo y forma | C40: ='4. Entregas 100%'!$B$4 -> Por asignar | D40: Finanzas | E40: ='4. Entregas 100%'!$B$5 -> 1 | F40: =IFERROR(LOOKUP(2,1/('4. Entregas 100%'!$D$11:$D$91<>""),'4. Entregas 100%'!$D$11:$D$91),"Sin datos") -> Sin datos | G40: =IFERROR(LOOKUP(2,1/('4. Entregas 100%'!$D$11:$D$91<>""),'4. Entregas 100%'!$H$11:$H$91),"Sin datos") -> Sin datos | H40: 4. Entregas 100%
A41: 5 | B41: Incrementar el MV de servicios basados en el DC GBM San Marcos en $20,000 | C41: ='5. MV Datacenter'!$B$4 -> Por asignar | D41: Pre-Sales, Del - DC | E41: ='5. MV Datacenter'!$B$5 -> 20000 | F41: =IFERROR(LOOKUP(2,1/('5. MV Datacenter'!$D$11:$D$91<>""),'5. MV Datacenter'!$D$11:$D$91),"Sin datos") -> Sin datos | G41: =IFERROR(LOOKUP(2,1/('5. MV Datacenter'!$D$11:$D$91<>""),'5. MV Datacenter'!$H$11:$H$91),"Sin datos") -> Sin datos | H41: 5. MV Datacenter
A42: 6 | B42: Tener cero contratos expired en al menos 16 de los próximos 18 meses | C42: ='6. Cero Expired'!$B$4 -> Por asignar | D42: Customer Success, Del - DEX, Del - TSS, Del - DC | E42: ='6. Cero Expired'!$B$5 -> 0 | F42: =IFERROR(LOOKUP(2,1/('6. Cero Expired'!$D$11:$D$91<>""),'6. Cero Expired'!$D$11:$D$91),"Sin datos") -> Sin datos | G42: =IFERROR(LOOKUP(2,1/('6. Cero Expired'!$D$11:$D$91<>""),'6. Cero Expired'!$H$11:$H$91),"Sin datos") -> Sin datos | H42: 6. Cero Expired
A43: 7 | B43: Incrementar el MV de Digital Solutions en $30K/mes al 1ro de mayo 2027 | C43: ='7. MV Digital Sol'!$B$4 -> Por asignar | D43: Ventas, Del - DS | E43: ='7. MV Digital Sol'!$B$5 -> 30000 | F43: =IFERROR(LOOKUP(2,1/('7. MV Digital Sol'!$D$11:$D$56<>""),'7. MV Digital Sol'!$D$11:$D$56),"Sin datos") -> Sin datos | G43: =IFERROR(LOOKUP(2,1/('7. MV Digital Sol'!$D$11:$D$56<>""),'7. MV Digital Sol'!$H$11:$H$56),"Sin datos") -> Sin datos | H43: 7. MV Digital Sol
A44: 8 | B44: Lograr un GP consolidado de 16% en el 2027 | C44: ='8. GP 16%'!$B$4 -> Por asignar | D44: Finanzas (todas las áreas aportan) | E44: ='8. GP 16%'!$B$5 -> 0.16 | F44: =IFERROR(LOOKUP(2,1/('8. GP 16%'!$D$11:$D$28<>""),'8. GP 16%'!$D$11:$D$28),"Sin datos") -> Sin datos | G44: =IFERROR(LOOKUP(2,1/('8. GP 16%'!$D$11:$D$28<>""),'8. GP 16%'!$H$11:$H$28),"Sin datos") -> Sin datos | H44: 8. GP 16%
A45: 9 | B45: Incrementar el CSAT de X a Y, sosteniéndolo 4 meses consecutivos | C45: ='9. CSAT'!$B$4 -> Por asignar | D45: Customer Success (todas las áreas de entrega aportan) | E45: ='9. CSAT'!$B$5 -> 4.5 | F45: =IFERROR(LOOKUP(2,1/('9. CSAT'!$D$11:$D$28<>""),'9. CSAT'!$D$11:$D$28),"Sin datos") -> Sin datos | G45: =IFERROR(LOOKUP(2,1/('9. CSAT'!$D$11:$D$28<>""),'9. CSAT'!$H$11:$H$28),"Sin datos") -> Sin datos | H45: 9. CSAT
...

Sheet 1. Smart User 500
A1: WIG 1 — Incrementar el Parque de Smart User en 500 equipos en el 2026
A2: Indicador lag: | B2: Equipos Smart User colocados (acumulado). 500 equipos a $40/mes = $6.4K MRR adicional en GP.
A3: De X a Y: | B3: De 0 a 500 equipos colocados, antes del 31 de diciembre de 2026.
A4: Dueño: | B4: Por asignar | D4: Equipo: | E4: Pre-Sales, Del - DEX
A5: Meta: | B5: 500 | D5: Inicio: | E5: 46188 | G5: Fin: | H5: 46384
A6: Leads: | B6: Hasta 8 indicadores predictivos a la derecha. L1–L2 = apuesta principal del equipo; L3–L8 = indicadores de apoyo. Nombre (fila 8) y meta semanal (fila 9) editables en azul.
A8: Periodos: | B8: =COUNT(A11:A39) -> 29 | H8: Lead → | I8: L1. Compromisos de asignación firmados (equipos) | K8: L2. Demos / POCs activos (Promerica, Disnorte, otros) | M8: L3. Presentaciones de oferta Smart User realizadas | O8: L4. Equipos cotizados en la semana | Q8: L5. Equipos en bodega listos para colocar | S8: L6. Clientes nuevos contactados con la oferta | U8: L7. % equipos colocados en ≤2 semanas tras firma | W8: (Disponible)
A9: Celdas azules = se digitan cada lunes. Celdas negras = fórmulas, no tocar. | H9: Meta → | I9: 20 | K9: 2 | M9: 3 | O9: 30 | Q9: 40 | S9: 2 | U9: 1
A10: # | B10: Semana | C10: Meta semana | D10: Real | E10: Meta acum. | F10: Real acum. | G10: % avance | H10: Estado | I10: Real | J10: % | K10: Real | L10: % | M10: Real | N10: % | O10: Real | P10: % | Q10: Real | R10: % | S10: Real | T10: % | U10: Real | V10: % | W10: Real | X10: %
A11: 1 | B11: 46188 | C11: =$B$5/$B$8 -> 17.241379 | E11: =SUM($C$11:C11) -> 17.241379 | F11: =SUM($D$11:D11) -> 0 | G11: =IF(COUNT($D$11:D11)=0,"",F11/E11) | H11: =IF(G11="","",IF(G11>=0.95,"En meta",IF(G11>=0.8,"Riesgo","Atrasado"))) | J11: =IF(I11="","",IF($I$9="","",IF($I$9=0,"",I11/$I$9))) | L11: =IF(K11="","",IF($K$9="","",IF($K$9=0,"",K11/$K$9))) | N11: =IF(M11="","",IF($M$9="","",IF($M$9=0,"",M11/$M$9))) | P11: =IF(O11="","",IF($O$9="","",IF($O$9=0,"",O11/$O$9))) | R11: =IF(Q11="","",IF($Q$9="","",IF($Q$9=0,"",Q11/$Q$9))) | T11: =IF(S11="","",IF($S$9="","",IF($S$9=0,"",S11/$S$9))) | V11: =IF(U11="","",IF($U$9="","",IF($U$9=0,"",U11/$U$9))) | X11: =IF(W11="","",IF($W$9="","",IF($W$9=0,"",W11/$W$9)))
A12: 2 | B12: 46195 | C12: =$B$5/$B$8 -> 17.241379 | E12: =SUM($C$11:C12) -> 34.482759 | F12: =SUM($D$11:D12) -> 0 | G12: =IF(COUNT($D$11:D12)=0,"",F12/E12) | H12: =IF(G12="","",IF(G12>=0.95,"En meta",IF(G12>=0.8,"Riesgo","Atrasado"))) | J12: =IF(I12="","",IF($I$9="","",IF($I$9=0,"",I12/$I$9))) | L12: =IF(K12="","",IF($K$9="","",IF($K$9=0,"",K12/$K$9))) | N12: =IF(M12="","",IF($M$9="","",IF($M$9=0,"",M12/$M$9))) | P12: =IF(O12="","",IF($O$9="","",IF($O$9=0,"",O12/$O$9))) | R12: =IF(Q12="","",IF($Q$9="","",IF($Q$9=0,"",Q12/$Q$9))) | T12: =IF(S12="","",IF($S$9="","",IF($S$9=0,"",S12/$S$9))) | V12: =IF(U12="","",IF($U$9="","",IF($U$9=0,"",U12/$U$9))) | X12: =IF(W12="","",IF($W$9="","",IF($W$9=0,"",W12/$W$9)))
A13: 3 | B13: 46202 | C13: =$B$5/$B$8 -> 17.241379 | E13: =SUM($C$11:C13) -> 51.724138 | F13: =SUM($D$11:D13) -> 0 | G13: =IF(COUNT($D$11:D13)=0,"",F13/E13) | H13: =IF(G13="","",IF(G13>=0.95,"En meta",IF(G13>=0.8,"Riesgo","Atrasado"))) | J13: =IF(I13="","",IF($I$9="","",IF($I$9=0,"",I13/$I$9))) | L13: =IF(K13="","",IF($K$9="","",IF($K$9=0,"",K13/$K$9))) | N13: =IF(M13="","",IF($M$9="","",IF($M$9=0,"",M13/$M$9))) | P13: =IF(O13="","",IF($O$9="","",IF($O$9=0,"",O13/$O$9))) | R13: =IF(Q13="","",IF($Q$9="","",IF($Q$9=0,"",Q13/$Q$9))) | T13: =IF(S13="","",IF($S$9="","",IF($S$9=0,"",S13/$S$9))) | V13: =IF(U13="","",IF($U$9="","",IF($U$9=0,"",U13/$U$9))) | X13: =IF(W13="","",IF($W$9="","",IF($W$9=0,"",W13/$W$9)))
A14: 4 | B14: 46209 | C14: =$B$5/$B$8 -> 17.241379 | E14: =SUM($C$11:C14) -> 68.965517 | F14: =SUM($D$11:D14) -> 0 | G14: =IF(COUNT($D$11:D14)=0,"",F14/E14) | H14: =IF(G14="","",IF(G14>=0.95,"En meta",IF(G14>=0.8,"Riesgo","Atrasado"))) | J14: =IF(I14="","",IF($I$9="","",IF($I$9=0,"",I14/$I$9))) | L14: =IF(K14="","",IF($K$9="","",IF($K$9=0,"",K14/$K$9))) | N14: =IF(M14="","",IF($M$9="","",IF($M$9=0,"",M14/$M$9))) | P14: =IF(O14="","",IF($O$9="","",IF($O$9=0,"",O14/$O$9))) | R14: =IF(Q14="","",IF($Q$9="","",IF($Q$9=0,"",Q14/$Q$9))) | T14: =IF(S14="","",IF($S$9="","",IF($S$9=0,"",S14/$S$9))) | V14: =IF(U14="","",IF($U$9="","",IF($U$9=0,"",U14/$U$9))) | X14: =IF(W14="","",IF($W$9="","",IF($W$9=0,"",W14/$W$9)))
A15: 5 | B15: 46216 | C15: =$B$5/$B$8 -> 17.241379 | E15: =SUM($C$11:C15) -> 86.206897 | F15: =SUM($D$11:D15) -> 0 | G15: =IF(COUNT($D$11:D15)=0,"",F15/E15) | H15: =IF(G15="","",IF(G15>=0.95,"En meta",IF(G15>=0.8,"Riesgo","Atrasado"))) | J15: =IF(I15="","",IF($I$9="","",IF($I$9=0,"",I15/$I$9))) | L15: =IF(K15="","",IF($K$9="","",IF($K$9=0,"",K15/$K$9))) | N15: =IF(M15="","",IF($M$9="","",IF($M$9=0,"",M15/$M$9))) | P15: =IF(O15="","",IF($O$9="","",IF($O$9=0,"",O15/$O$9))) | R15: =IF(Q15="","",IF($Q$9="","",IF($Q$9=0,"",Q15/$Q$9))) | T15: =IF(S15="","",IF($S$9="","",IF($S$9=0,"",S15/$S$9))) | V15: =IF(U15="","",IF($U$9="","",IF($U$9=0,"",U15/$U$9))) | X15: =IF(W15="","",IF($W$9="","",IF($W$9=0,"",W15/$W$9)))
A16: 6 | B16: 46223 | C16: =$B$5/$B$8 -> 17.241379 | E16: =SUM($C$11:C16) -> 103.44828 | F16: =SUM($D$11:D16) -> 0 | G16: =IF(COUNT($D$11:D16)=0,"",F16/E16) | H16: =IF(G16="","",IF(G16>=0.95,"En meta",IF(G16>=0.8,"Riesgo","Atrasado"))) | J16: =IF(I16="","",IF($I$9="","",IF($I$9=0,"",I16/$I$9))) | L16: =IF(K16="","",IF($K$9="","",IF($K$9=0,"",K16/$K$9))) | N16: =IF(M16="","",IF($M$9="","",IF($M$9=0,"",M16/$M$9))) | P16: =IF(O16="","",IF($O$9="","",IF($O$9=0,"",O16/$O$9))) | R16: =IF(Q16="","",IF($Q$9="","",IF($Q$9=0,"",Q16/$Q$9))) | T16: =IF(S16="","",IF($S$9="","",IF($S$9=0,"",S16/$S$9))) | V16: =IF(U16="","",IF($U$9="","",IF($U$9=0,"",U16/$U$9))) | X16: =IF(W16="","",IF($W$9="","",IF($W$9=0,"",W16/$W$9)))
A17: 7 | B17: 46230 | C17: =$B$5/$B$8 -> 17.241379 | E17: =SUM($C$11:C17) -> 120.68966 | F17: =SUM($D$11:D17) -> 0 | G17: =IF(COUNT($D$11:D17)=0,"",F17/E17) | H17: =IF(G17="","",IF(G17>=0.95,"En meta",IF(G17>=0.8,"Riesgo","Atrasado"))) | J17: =IF(I17="","",IF($I$9="","",IF($I$9=0,"",I17/$I$9))) | L17: =IF(K17="","",IF($K$9="","",IF($K$9=0,"",K17/$K$9))) | N17: =IF(M17="","",IF($M$9="","",IF($M$9=0,"",M17/$M$9))) | P17: =IF(O17="","",IF($O$9="","",IF($O$9=0,"",O17/$O$9))) | R17: =IF(Q17="","",IF($Q$9="","",IF($Q$9=0,"",Q17/$Q$9))) | T17: =IF(S17="","",IF($S$9="","",IF($S$9=0,"",S17/$S$9))) | V17: =IF(U17="","",IF($U$9="","",IF($U$9=0,"",U17/$U$9))) | X17: =IF(W17="","",IF($W$9="","",IF($W$9=0,"",W17/$W$9)))
A18: 8 | B18: 46237 | C18: =$B$5/$B$8 -> 17.241379 | E18: =SUM($C$11:C18) -> 137.93103 | F18: =SUM($D$11:D18) -> 0 | G18: =IF(COUNT($D$11:D18)=0,"",F18/E18) | H18: =IF(G18="","",IF(G18>=0.95,"En meta",IF(G18>=0.8,"Riesgo","Atrasado"))) | J18: =IF(I18="","",IF($I$9="","",IF($I$9=0,"",I18/$I$9))) | L18: =IF(K18="","",IF($K$9="","",IF($K$9=0,"",K18/$K$9))) | N18: =IF(M18="","",IF($M$9="","",IF($M$9=0,"",M18/$M$9))) | P18: =IF(O18="","",IF($O$9="","",IF($O$9=0,"",O18/$O$9))) | R18: =IF(Q18="","",IF($Q$9="","",IF($Q$9=0,"",Q18/$Q$9))) | T18: =IF(S18="","",IF($S$9="","",IF($S$9=0,"",S18/$S$9))) | V18: =IF(U18="","",IF($U$9="","",IF($U$9=0,"",U18/$U$9))) | X18: =IF(W18="","",IF($W$9="","",IF($W$9=0,"",W18/$W$9)))
A19: 9 | B19: 46244 | C19: =$B$5/$B$8 -> 17.241379 | E19: =SUM($C$11:C19) -> 155.17241 | F19: =SUM($D$11:D19) -> 0 | G19: =IF(COUNT($D$11:D19)=0,"",F19/E19) | H19: =IF(G19="","",IF(G19>=0.95,"En meta",IF(G19>=0.8,"Riesgo","Atrasado"))) | J19: =IF(I19="","",IF($I$9="","",IF($I$9=0,"",I19/$I$9))) | L19: =IF(K19="","",IF($K$9="","",IF($K$9=0,"",K19/$K$9))) | N19: =IF(M19="","",IF($M$9="","",IF($M$9=0,"",M19/$M$9))) | P19: =IF(O19="","",IF($O$9="","",IF($O$9=0,"",O19/$O$9))) | R19: =IF(Q19="","",IF($Q$9="","",IF($Q$9=0,"",Q19/$Q$9))) | T19: =IF(S19="","",IF($S$9="","",IF($S$9=0,"",S19/$S$9))) | V19: =IF(U19="","",IF($U$9="","",IF($U$9=0,"",U19/$U$9))) | X19: =IF(W19="","",IF($W$9="","",IF($W$9=0,"",W19/$W$9)))
A20: 10 | B20: 46251 | C20: =$B$5/$B$8 -> 17.241379 | E20: =SUM($C$11:C20) -> 172.41379 | F20: =SUM($D$11:D20) -> 0 | G20: =IF(COUNT($D$11:D20)=0,"",F20/E20) | H20: =IF(G20="","",IF(G20>=0.95,"En meta",IF(G20>=0.8,"Riesgo","Atrasado"))) | J20: =IF(I20="","",IF($I$9="","",IF($I$9=0,"",I20/$I$9))) | L20: =IF(K20="","",IF($K$9="","",IF($K$9=0,"",K20/$K$9))) | N20: =IF(M20="","",IF($M$9="","",IF($M$9=0,"",M20/$M$9))) | P20: =IF(O20="","",IF($O$9="","",IF($O$9=0,"",O20/$O$9))) | R20: =IF(Q20="","",IF($Q$9="","",IF($Q$9=0,"",Q20/$Q$9))) | T20: =IF(S20="","",IF($S$9="","",IF($S$9=0,"",S20/$S$9))) | V20: =IF(U20="","",IF($U$9="","",IF($U$9=0,"",U20/$U$9))) | X20: =IF(W20="","",IF($W$9="","",IF($W$9=0,"",W20/$W$9)))
A21: 11 | B21: 46258 | C21: =$B$5/$B$8 -> 17.241379 | E21: =SUM($C$11:C21) -> 189.65517 | F21: =SUM($D$11:D21) -> 0 | G21: =IF(COUNT($D$11:D21)=0,"",F21/E21) | H21: =IF(G21="","",IF(G21>=0.95,"En meta",IF(G21>=0.8,"Riesgo","Atrasado"))) | J21: =IF(I21="","",IF($I$9="","",IF($I$9=0,"",I21/$I$9))) | L21: =IF(K21="","",IF($K$9="","",IF($K$9=0,"",K21/$K$9))) | N21: =IF(M21="","",IF($M$9="","",IF($M$9=0,"",M21/$M$9))) | P21: =IF(O21="","",IF($O$9="","",IF($O$9=0,"",O21/$O$9))) | R21: =IF(Q21="","",IF($Q$9="","",IF($Q$9=0,"",Q21/$Q$9))) | T21: =IF(S21="","",IF($S$9="","",IF($S$9=0,"",S21/$S$9))) | V21: =IF(U21="","",IF($U$9="","",IF($U$9=0,"",U21/$U$9))) | X21: =IF(W21="","",IF($W$9="","",IF($W$9=0,"",W21/$W$9)))
A22: 12 | B22: 46265 | C22: =$B$5/$B$8 -> 17.241379 | E22: =SUM($C$11:C22) -> 206.89655 | F22: =SUM($D$11:D22) -> 0 | G22: =IF(COUNT($D$11:D22)=0,"",F22/E22) | H22: =IF(G22="","",IF(G22>=0.95,"En meta",IF(G22>=0.8,"Riesgo","Atrasado"))) | J22: =IF(I22="","",IF($I$9="","",IF($I$9=0,"",I22/$I$9))) | L22: =IF(K22="","",IF($K$9="","",IF($K$9=0,"",K22/$K$9))) | N22: =IF(M22="","",IF($M$9="","",IF($M$9=0,"",M22/$M$9))) | P22: =IF(O22="","",IF($O$9="","",IF($O$9=0,"",O22/$O$9))) | R22: =IF(Q22="","",IF($Q$9="","",IF($Q$9=0,"",Q22/$Q$9))) | T22: =IF(S22="","",IF($S$9="","",IF($S$9=0,"",S22/$S$9))) | V22: =IF(U22="","",IF($U$9="","",IF($U$9=0,"",U22/$U$9))) | X22: =IF(W22="","",IF($W$9="","",IF($W$9=0,"",W22/$W$9)))
... A39: 29 | B39: 46384 | C39: =$B$5/$B$8 -> 17.241379 | E39: =SUM($C$11:C39) -> 500 | F39: =SUM($D$11:D39) -> 0 | G39: =IF(COUNT($D$11:D39)=0,"",F39/E39) | H39: =IF(G39="","",IF(G39>=0.95,"En meta",IF(G39>=0.8,"Riesgo","Atrasado"))) | J39: =IF(I39="","",IF($I$9="","",IF($I$9=0,"",I39/$I$9))) | L39: =IF(K39="","",IF($K$9="","",IF($K$9=0,"",K39/$K$9))) | N39: =IF(M39="","",IF($M$9="","",IF($M$9=0,"",M39/$M$9))) | P39: =IF(O39="","",IF($O$9="","",IF($O$9=0,"",O39/$O$9))) | R39: =IF(Q39="","",IF($Q$9="","",IF($Q$9=0,"",Q39/$Q$9))) | T39: =IF(S39="","",IF($S$9="","",IF($S$9=0,"",S39/$S$9))) | V39: =IF(U39="","",IF($U$9="","",IF($U$9=0,"",U39/$U$9))) | X39: =IF(W39="","",IF($W$9="","",IF($W$9=0,"",W39/$W$9)))

Sheet 2. MV Advisory
A1: WIG 2 — Lograr un Monthly Value de $X en advisory en el primer trimestre de 2027
A2: Indicador lag: | B2: MV de horas advisory de ingenieros locales vendidas (USD acumulado). Costo fijo ya cubierto = mayor utilidad.
A3: De X a Y: | B3: De $0 a la meta de MV advisory, antes del 31 de marzo de 2027. (Definir $X en la celda Meta)
A4: Dueño: | B4: Por asignar | D4: Equipo: | E4: Ventas, Customer Success, Pre-Sales, Del - TSS
A5: Meta: | B5: 10000 | D5: Inicio: | E5: 46188 | G5: Fin: | H5: 46475
A6: Leads: | B6: Hasta 8 indicadores predictivos a la derecha. L1–L2 = apuesta principal del equipo; L3–L8 = indicadores de apoyo. Nombre (fila 8) y meta semanal (fila 9) editables en azul.
A8: Periodos: | B8: =COUNT(A11:A52) -> 42 | H8: Lead → | I8: L1. Propuestas de advisory presentadas | K8: L2. Horas advisory cotizadas | M8: L3. Reuniones de venta consultiva con clientes | O8: L4. Assessments / health checks ofrecidos | Q8: L5. % utilización de ingenieros locales en advisory | S8: L6. Opps de advisory activas en pipeline | U8: L7. Contratos advisory firmados en la semana | W8: (Disponible)
A9: Celdas azules = se digitan cada lunes. Celdas negras = fórmulas, no tocar. | H9: Meta → | I9: 3 | K9: 40 | M9: 4 | O9: 2 | Q9: 0.2 | S9: 6 | U9: 1
A10: # | B10: Semana | C10: Meta semana | D10: Real | E10: Meta acum. | F10: Real acum. | G10: % avance | H10: Estado | I10: Real | J10: % | K10: Real | L10: % | M10: Real | N10: % | O10: Real | P10: % | Q10: Real | R10: % | S10: Real | T10: % | U10: Real | V10: % | W10: Real | X10: %
A11: 1 | B11: 46188 | C11: =$B$5/$B$8 -> 238.09524 | E11: =SUM($C$11:C11) -> 238.09524 | F11: =SUM($D$11:D11) -> 0 | G11: =IF(COUNT($D$11:D11)=0,"",F11/E11) | H11: =IF(G11="","",IF(G11>=0.95,"En meta",IF(G11>=0.8,"Riesgo","Atrasado"))) | J11: =IF(I11="","",IF($I$9="","",IF($I$9=0,"",I11/$I$9))) | L11: =IF(K11="","",IF($K$9="","",IF($K$9=0,"",K11/$K$9))) | N11: =IF(M11="","",IF($M$9="","",IF($M$9=0,"",M11/$M$9))) | P11: =IF(O11="","",IF($O$9="","",IF($O$9=0,"",O11/$O$9))) | R11: =IF(Q11="","",IF($Q$9="","",IF($Q$9=0,"",Q11/$Q$9))) | T11: =IF(S11="","",IF($S$9="","",IF($S$9=0,"",S11/$S$9))) | V11: =IF(U11="","",IF($U$9="","",IF($U$9=0,"",U11/$U$9))) | X11: =IF(W11="","",IF($W$9="","",IF($W$9=0,"",W11/$W$9)))
A12: 2 | B12: 46195 | C12: =$B$5/$B$8 -> 238.09524 | E12: =SUM($C$11:C12) -> 476.19048 | F12: =SUM($D$11:D12) -> 0 | G12: =IF(COUNT($D$11:D12)=0,"",F12/E12) | H12: =IF(G12="","",IF(G12>=0.95,"En meta",IF(G12>=0.8,"Riesgo","Atrasado"))) | J12: =IF(I12="","",IF($I$9="","",IF($I$9=0,"",I12/$I$9))) | L12: =IF(K12="","",IF($K$9="","",IF($K$9=0,"",K12/$K$9))) | N12: =IF(M12="","",IF($M$9="","",IF($M$9=0,"",M12/$M$9))) | P12: =IF(O12="","",IF($O$9="","",IF($O$9=0,"",O12/$O$9))) | R12: =IF(Q12="","",IF($Q$9="","",IF($Q$9=0,"",Q12/$Q$9))) | T12: =IF(S12="","",IF($S$9="","",IF($S$9=0,"",S12/$S$9))) | V12: =IF(U12="","",IF($U$9="","",IF($U$9=0,"",U12/$U$9))) | X12: =IF(W12="","",IF($W$9="","",IF($W$9=0,"",W12/$W$9)))
A13: 3 | B13: 46202 | C13: =$B$5/$B$8 -> 238.09524 | E13: =SUM($C$11:C13) -> 714.28571 | F13: =SUM($D$11:D13) -> 0 | G13: =IF(COUNT($D$11:D13)=0,"",F13/E13) | H13: =IF(G13="","",IF(G13>=0.95,"En meta",IF(G13>=0.8,"Riesgo","Atrasado"))) | J13: =IF(I13="","",IF($I$9="","",IF($I$9=0,"",I13/$I$9))) | L13: =IF(K13="","",IF($K$9="","",IF($K$9=0,"",K13/$K$9))) | N13: =IF(M13="","",IF($M$9="","",IF($M$9=0,"",M13/$M$9))) | P13: =IF(O13="","",IF($O$9="","",IF($O$9=0,"",O13/$O$9))) | R13: =IF(Q13="","",IF($Q$9="","",IF($Q$9=0,"",Q13/$Q$9))) | T13: =IF(S13="","",IF($S$9="","",IF($S$9=0,"",S13/$S$9))) | V13: =IF(U13="","",IF($U$9="","",IF($U$9=0,"",U13/$U$9))) | X13: =IF(W13="","",IF($W$9="","",IF($W$9=0,"",W13/$W$9)))
A14: 4 | B14: 46209 | C14: =$B$5/$B$8 -> 238.09524 | E14: =SUM($C$11:C14) -> 952.38095 | F14: =SUM($D$11:D14) -> 0 | G14: =IF(COUNT($D$11:D14)=0,"",F14/E14) | H14: =IF(G14="","",IF(G14>=0.95,"En meta",IF(G14>=0.8,"Riesgo","Atrasado"))) | J14: =IF(I14="","",IF($I$9="","",IF($I$9=0,"",I14/$I$9))) | L14: =IF(K14="","",IF($K$9="","",IF($K$9=0,"",K14/$K$9))) | N14: =IF(M14="","",IF($M$9="","",IF($M$9=0,"",M14/$M$9))) | P14: =IF(O14="","",IF($O$9="","",IF($O$9=0,"",O14/$O$9))) | R14: =IF(Q14="","",IF($Q$9="","",IF($Q$9=0,"",Q14/$Q$9))) | T14: =IF(S14="","",IF($S$9="","",IF($S$9=0,"",S14/$S$9))) | V14: =IF(U14="","",IF($U$9="","",IF($U$9=0,"",U14/$U$9))) | X14: =IF(W14="","",IF($W$9="","",IF($W$9=0,"",W14/$W$9)))
A15: 5 | B15: 46216 | C15: =$B$5/$B$8 -> 238.09524 | E15: =SUM($C$11:C15) -> 1190.4762 | F15: =SUM($D$11:D15) -> 0 | G15: =IF(COUNT($D$11:D15)=0,"",F15/E15) | H15: =IF(G15="","",IF(G15>=0.95,"En meta",IF(G15>=0.8,"Riesgo","Atrasado"))) | J15: =IF(I15="","",IF($I$9="","",IF($I$9=0,"",I15/$I$9))) | L15: =IF(K15="","",IF($K$9="","",IF($K$9=0,"",K15/$K$9))) | N15: =IF(M15="","",IF($M$9="","",IF($M$9=0,"",M15/$M$9))) | P15: =IF(O15="","",IF($O$9="","",IF($O$9=0,"",O15/$O$9))) | R15: =IF(Q15="","",IF($Q$9="","",IF($Q$9=0,"",Q15/$Q$9))) | T15: =IF(S15="","",IF($S$9="","",IF($S$9=0,"",S15/$S$9))) | V15: =IF(U15="","",IF($U$9="","",IF($U$9=0,"",U15/$U$9))) | X15: =IF(W15="","",IF($W$9="","",IF($W$9=0,"",W15/$W$9)))
A16: 6 | B16: 46223 | C16: =$B$5/$B$8 -> 238.09524 | E16: =SUM($C$11:C16) -> 1428.5714 | F16: =SUM($D$11:D16) -> 0 | G16: =IF(COUNT($D$11:D16)=0,"",F16/E16) | H16: =IF(G16="","",IF(G16>=0.95,"En meta",IF(G16>=0.8,"Riesgo","Atrasado"))) | J16: =IF(I16="","",IF($I$9="","",IF($I$9=0,"",I16/$I$9))) | L16: =IF(K16="","",IF($K$9="","",IF($K$9=0,"",K16/$K$9))) | N16: =IF(M16="","",IF($M$9="","",IF($M$9=0,"",M16/$M$9))) | P16: =IF(O16="","",IF($O$9="","",IF($O$9=0,"",O16/$O$9))) | R16: =IF(Q16="","",IF($Q$9="","",IF($Q$9=0,"",Q16/$Q$9))) | T16: =IF(S16="","",IF($S$9="","",IF($S$9=0,"",S16/$S$9))) | V16: =IF(U16="","",IF($U$9="","",IF($U$9=0,"",U16/$U$9))) | X16: =IF(W16="","",IF($W$9="","",IF($W$9=0,"",W16/$W$9)))
A17: 7 | B17: 46230 | C17: =$B$5/$B$8 -> 238.09524 | E17: =SUM($C$11:C17) -> 1666.6667 | F17: =SUM($D$11:D17) -> 0 | G17: =IF(COUNT($D$11:D17)=0,"",F17/E17) | H17: =IF(G17="","",IF(G17>=0.95,"En meta",IF(G17>=0.8,"Riesgo","Atrasado"))) | J17: =IF(I17="","",IF($I$9="","",IF($I$9=0,"",I17/$I$9))) | L17: =IF(K17="","",IF($K$9="","",IF($K$9=0,"",K17/$K$9))) | N17: =IF(M17="","",IF($M$9="","",IF($M$9=0,"",M17/$M$9))) | P17: =IF(O17="","",IF($O$9="","",IF($O$9=0,"",O17/$O$9))) | R17: =IF(Q17="","",IF($Q$9="","",IF($Q$9=0,"",Q17/$Q$9))) | T17: =IF(S17="","",IF($S$9="","",IF($S$9=0,"",S17/$S$9))) | V17: =IF(U17="","",IF($U$9="","",IF($U$9=0,"",U17/$U$9))) | X17: =IF(W17="","",IF($W$9="","",IF($W$9=0,"",W17/$W$9)))
A18: 8 | B18: 46237 | C18: =$B$5/$B$8 -> 238.09524 | E18: =SUM($C$11:C18) -> 1904.7619 | F18: =SUM($D$11:D18) -> 0 | G18: =IF(COUNT($D$11:D18)=0,"",F18/E18) | H18: =IF(G18="","",IF(G18>=0.95,"En meta",IF(G18>=0.8,"Riesgo","Atrasado"))) | J18: =IF(I18="","",IF($I$9="","",IF($I$9=0,"",I18/$I$9))) | L18: =IF(K18="","",IF($K$9="","",IF($K$9=0,"",K18/$K$9))) | N18: =IF(M18="","",IF($M$9="","",IF($M$9=0,"",M18/$M$9))) | P18: =IF(O18="","",IF($O$9="","",IF($O$9=0,"",O18/$O$9))) | R18: =IF(Q18="","",IF($Q$9="","",IF($Q$9=0,"",Q18/$Q$9))) | T18: =IF(S18="","",IF($S$9="","",IF($S$9=0,"",S18/$S$9))) | V18: =IF(U18="","",IF($U$9="","",IF($U$9=0,"",U18/$U$9))) | X18: =IF(W18="","",IF($W$9="","",IF($W$9=0,"",W18/$W$9)))
A19: 9 | B19: 46244 | C19: =$B$5/$B$8 -> 238.09524 | E19: =SUM($C$11:C19) -> 2142.8571 | F19: =SUM($D$11:D19) -> 0 | G19: =IF(COUNT($D$11:D19)=0,"",F19/E19) | H19: =IF(G19="","",IF(G19>=0.95,"En meta",IF(G19>=0.8,"Riesgo","Atrasado"))) | J19: =IF(I19="","",IF($I$9="","",IF($I$9=0,"",I19/$I$9))) | L19: =IF(K19="","",IF($K$9="","",IF($K$9=0,"",K19/$K$9))) | N19: =IF(M19="","",IF($M$9="","",IF($M$9=0,"",M19/$M$9))) | P19: =IF(O19="","",IF($O$9="","",IF($O$9=0,"",O19/$O$9))) | R19: =IF(Q19="","",IF($Q$9="","",IF($Q$9=0,"",Q19/$Q$9))) | T19: =IF(S19="","",IF($S$9="","",IF($S$9=0,"",S19/$S$9))) | V19: =IF(U19="","",IF($U$9="","",IF($U$9=0,"",U19/$U$9))) | X19: =IF(W19="","",IF($W$9="","",IF($W$9=0,"",W19/$W$9)))
A20: 10 | B20: 46251 | C20: =$B$5/$B$8 -> 238.09524 | E20: =SUM($C$11:C20) -> 2380.9524 | F20: =SUM($D$11:D20) -> 0 | G20: =IF(COUNT($D$11:D20)=0,"",F20/E20) | H20: =IF(G20="","",IF(G20>=0.95,"En meta",IF(G20>=0.8,"Riesgo","Atrasado"))) | J20: =IF(I20="","",IF($I$9="","",IF($I$9=0,"",I20/$I$9))) | L20: =IF(K20="","",IF($K$9="","",IF($K$9=0,"",K20/$K$9))) | N20: =IF(M20="","",IF($M$9="","",IF($M$9=0,"",M20/$M$9))) | P20: =IF(O20="","",IF($O$9="","",IF($O$9=0,"",O20/$O$9))) | R20: =IF(Q20="","",IF($Q$9="","",IF($Q$9=0,"",Q20/$Q$9))) | T20: =IF(S20="","",IF($S$9="","",IF($S$9=0,"",S20/$S$9))) | V20: =IF(U20="","",IF($U$9="","",IF($U$9=0,"",U20/$U$9))) | X20: =IF(W20="","",IF($W$9="","",IF($W$9=0,"",W20/$W$9)))
A21: 11 | B21: 46258 | C21: =$B$5/$B$8 -> 238.09524 | E21: =SUM($C$11:C21) -> 2619.0476 | F21: =SUM($D$11:D21) -> 0 | G21: =IF(COUNT($D$11:D21)=0,"",F21/E21) | H21: =IF(G21="","",IF(G21>=0.95,"En meta",IF(G21>=0.8,"Riesgo","Atrasado"))) | J21: =IF(I21="","",IF($I$9="","",IF($I$9=0,"",I21/$I$9))) | L21: =IF(K21="","",IF($K$9="","",IF($K$9=0,"",K21/$K$9))) | N21: =IF(M21="","",IF($M$9="","",IF($M$9=0,"",M21/$M$9))) | P21: =IF(O21="","",IF($O$9="","",IF($O$9=0,"",O21/$O$9))) | R21: =IF(Q21="","",IF($Q$9="","",IF($Q$9=0,"",Q21/$Q$9))) | T21: =IF(S21="","",IF($S$9="","",IF($S$9=0,"",S21/$S$9))) | V21: =IF(U21="","",IF($U$9="","",IF($U$9=0,"",U21/$U$9))) | X21: =IF(W21="","",IF($W$9="","",IF($W$9=0,"",W21/$W$9)))
A22: 12 | B22: 46265 | C22: =$B$5/$B$8 -> 238.09524 | E22: =SUM($C$11:C22) -> 2857.1429 | F22: =SUM($D$11:D22) -> 0 | G22: =IF(COUNT($D$11:D22)=0,"",F22/E22) | H22: =IF(G22="","",IF(G22>=0.95,"En meta",IF(G22>=0.8,"Riesgo","Atrasado"))) | J22: =IF(I22="","",IF($I$9="","",IF($I$9=0,"",I22/$I$9))) | L22: =IF(K22="","",IF($K$9="","",IF($K$9=0,"",K22/$K$9))) | N22: =IF(M22="","",IF($M$9="","",IF($M$9=0,"",M22/$M$9))) | P22: =IF(O22="","",IF($O$9="","",IF($O$9=0,"",O22/$O$9))) | R22: =IF(Q22="","",IF($Q$9="","",IF($Q$9=0,"",Q22/$Q$9))) | T22: =IF(S22="","",IF($S$9="","",IF($S$9=0,"",S22/$S$9))) | V22: =IF(U22="","",IF($U$9="","",IF($U$9=0,"",U22/$U$9))) | X22: =IF(W22="","",IF($W$9="","",IF($W$9=0,"",W22/$W$9)))
... A52: 42 | B52: 46475 | C52: =$B$5/$B$8 -> 238.09524 | E52: =SUM($C$11:C52) -> 10000 | F52: =SUM($D$11:D52) -> 0 | G52: =IF(COUNT($D$11:D52)=0,"",F52/E52) | H52: =IF(G52="","",IF(G52>=0.95,"En meta",IF(G52>=0.8,"Riesgo","Atrasado"))) | J52: =IF(I52="","",IF($I$9="","",IF($I$9=0,"",I52/$I$9))) | L52: =IF(K52="","",IF($K$9="","",IF($K$9=0,"",K52/$K$9))) | N52: =IF(M52="","",IF($M$9="","",IF($M$9=0,"",M52/$M$9))) | P52: =IF(O52="","",IF($O$9="","",IF($O$9=0,"",O52/$O$9))) | R52: =IF(Q52="","",IF($Q$9="","",IF($Q$9=0,"",Q52/$Q$9))) | T52: =IF(S52="","",IF($S$9="","",IF($S$9=0,"",S52/$S$9))) | V52: =IF(U52="","",IF($U$9="","",IF($U$9=0,"",U52/$U$9))) | X52: =IF(W52="","",IF($W$9="","",IF($W$9=0,"",W52/$W$9)))

Sheet 3. Negocios +30K GP
A1: WIG 3 — Reconocer 10 negocios mayores a $30K de GP en el 2027
A2: Indicador lag: | B2: Negocios con GP > $30K reconocidos (acumulado). Negocios grandes que mueven el NAT.
A3: De X a Y: | B3: De 0 a 10 negocios > $30K GP reconocidos, antes del 31 de diciembre de 2027.
A4: Dueño: | B4: Por asignar | D4: Equipo: | E4: Ventas, Pre-Sales
A5: Meta: | B5: 10 | D5: Inicio: | E5: 46188 | G5: Fin: | H5: 46748
A6: Leads: | B6: Hasta 8 indicadores predictivos a la derecha. L1–L2 = apuesta principal del equipo; L3–L8 = indicadores de apoyo. Nombre (fila 8) y meta semanal (fila 9) editables en azul.
A8: Periodos: | B8: =COUNT(A11:A91) -> 81 | H8: Lead → | I8: L1. Opps > $30K GP activas en pipeline | K8: L2. Opps nuevas ingresadas en la semana | M8: L3. Propuestas > $30K presentadas | O8: L4. Reuniones C-level realizadas | Q8: L5. Leads activas al cierre de la semana | S8: L6. Opps > $30K avanzadas de etapa | U8: L7. Win rate de opps > $30K (acumulado) | W8: (Disponible)
A9: Celdas azules = se digitan cada lunes. Celdas negras = fórmulas, no tocar. | H9: Meta → | I9: 5 | K9: 4 | M9: 1 | O9: 2 | Q9: 10 | S9: 2 | U9: 0.3
A10: # | B10: Semana | C10: Meta semana | D10: Real | E10: Meta acum. | F10: Real acum. | G10: % avance | H10: Estado | I10: Real | J10: % | K10: Real | L10: % | M10: Real | N10: % | O10: Real | P10: % | Q10: Real | R10: % | S10: Real | T10: % | U10: Real | V10: % | W10: Real | X10: %
A11: 1 | B11: 46188 | C11: =$B$5/$B$8 -> 0.12345679 | E11: =SUM($C$11:C11) -> 0.12345679 | F11: =SUM($D$11:D11) -> 0 | G11: =IF(COUNT($D$11:D11)=0,"",F11/E11) | H11: =IF(G11="","",IF(G11>=0.95,"En meta",IF(G11>=0.8,"Riesgo","Atrasado"))) | J11: =IF(I11="","",IF($I$9="","",IF($I$9=0,"",I11/$I$9))) | L11: =IF(K11="","",IF($K$9="","",IF($K$9=0,"",K11/$K$9))) | N11: =IF(M11="","",IF($M$9="","",IF($M$9=0,"",M11/$M$9))) | P11: =IF(O11="","",IF($O$9="","",IF($O$9=0,"",O11/$O$9))) | R11: =IF(Q11="","",IF($Q$9="","",IF($Q$9=0,"",Q11/$Q$9))) | T11: =IF(S11="","",IF($S$9="","",IF($S$9=0,"",S11/$S$9))) | V11: =IF(U11="","",IF($U$9="","",IF($U$9=0,"",U11/$U$9))) | X11: =IF(W11="","",IF($W$9="","",IF($W$9=0,"",W11/$W$9)))
A12: 2 | B12: 46195 | C12: =$B$5/$B$8 -> 0.12345679 | E12: =SUM($C$11:C12) -> 0.24691358 | F12: =SUM($D$11:D12) -> 0 | G12: =IF(COUNT($D$11:D12)=0,"",F12/E12) | H12: =IF(G12="","",IF(G12>=0.95,"En meta",IF(G12>=0.8,"Riesgo","Atrasado"))) | J12: =IF(I12="","",IF($I$9="","",IF($I$9=0,"",I12/$I$9))) | L12: =IF(K12="","",IF($K$9="","",IF($K$9=0,"",K12/$K$9))) | N12: =IF(M12="","",IF($M$9="","",IF($M$9=0,"",M12/$M$9))) | P12: =IF(O12="","",IF($O$9="","",IF($O$9=0,"",O12/$O$9))) | R12: =IF(Q12="","",IF($Q$9="","",IF($Q$9=0,"",Q12/$Q$9))) | T12: =IF(S12="","",IF($S$9="","",IF($S$9=0,"",S12/$S$9))) | V12: =IF(U12="","",IF($U$9="","",IF($U$9=0,"",U12/$U$9))) | X12: =IF(W12="","",IF($W$9="","",IF($W$9=0,"",W12/$W$9)))
A13: 3 | B13: 46202 | C13: =$B$5/$B$8 -> 0.12345679 | E13: =SUM($C$11:C13) -> 0.37037037 | F13: =SUM($D$11:D13) -> 0 | G13: =IF(COUNT($D$11:D13)=0,"",F13/E13) | H13: =IF(G13="","",IF(G13>=0.95,"En meta",IF(G13>=0.8,"Riesgo","Atrasado"))) | J13: =IF(I13="","",IF($I$9="","",IF($I$9=0,"",I13/$I$9))) | L13: =IF(K13="","",IF($K$9="","",IF($K$9=0,"",K13/$K$9))) | N13: =IF(M13="","",IF($M$9="","",IF($M$9=0,"",M13/$M$9))) | P13: =IF(O13="","",IF($O$9="","",IF($O$9=0,"",O13/$O$9))) | R13: =IF(Q13="","",IF($Q$9="","",IF($Q$9=0,"",Q13/$Q$9))) | T13: =IF(S13="","",IF($S$9="","",IF($S$9=0,"",S13/$S$9))) | V13: =IF(U13="","",IF($U$9="","",IF($U$9=0,"",U13/$U$9))) | X13: =IF(W13="","",IF($W$9="","",IF($W$9=0,"",W13/$W$9)))
A14: 4 | B14: 46209 | C14: =$B$5/$B$8 -> 0.12345679 | E14: =SUM($C$11:C14) -> 0.49382716 | F14: =SUM($D$11:D14) -> 0 | G14: =IF(COUNT($D$11:D14)=0,"",F14/E14) | H14: =IF(G14="","",IF(G14>=0.95,"En meta",IF(G14>=0.8,"Riesgo","Atrasado"))) | J14: =IF(I14="","",IF($I$9="","",IF($I$9=0,"",I14/$I$9))) | L14: =IF(K14="","",IF($K$9="","",IF($K$9=0,"",K14/$K$9))) | N14: =IF(M14="","",IF($M$9="","",IF($M$9=0,"",M14/$M$9))) | P14: =IF(O14="","",IF($O$9="","",IF($O$9=0,"",O14/$O$9))) | R14: =IF(Q14="","",IF($Q$9="","",IF($Q$9=0,"",Q14/$Q$9))) | T14: =IF(S14="","",IF($S$9="","",IF($S$9=0,"",S14/$S$9))) | V14: =IF(U14="","",IF($U$9="","",IF($U$9=0,"",U14/$U$9))) | X14: =IF(W14="","",IF($W$9="","",IF($W$9=0,"",W14/$W$9)))
A15: 5 | B15: 46216 | C15: =$B$5/$B$8 -> 0.12345679 | E15: =SUM($C$11:C15) -> 0.61728395 | F15: =SUM($D$11:D15) -> 0 | G15: =IF(COUNT($D$11:D15)=0,"",F15/E15) | H15: =IF(G15="","",IF(G15>=0.95,"En meta",IF(G15>=0.8,"Riesgo","Atrasado"))) | J15: =IF(I15="","",IF($I$9="","",IF($I$9=0,"",I15/$I$9))) | L15: =IF(K15="","",IF($K$9="","",IF($K$9=0,"",K15/$K$9))) | N15: =IF(M15="","",IF($M$9="","",IF($M$9=0,"",M15/$M$9))) | P15: =IF(O15="","",IF($O$9="","",IF($O$9=0,"",O15/$O$9))) | R15: =IF(Q15="","",IF($Q$9="","",IF($Q$9=0,"",Q15/$Q$9))) | T15: =IF(S15="","",IF($S$9="","",IF($S$9=0,"",S15/$S$9))) | V15: =IF(U15="","",IF($U$9="","",IF($U$9=0,"",U15/$U$9))) | X15: =IF(W15="","",IF($W$9="","",IF($W$9=0,"",W15/$W$9)))
A16: 6 | B16: 46223 | C16: =$B$5/$B$8 -> 0.12345679 | E16: =SUM($C$11:C16) -> 0.74074074 | F16: =SUM($D$11:D16) -> 0 | G16: =IF(COUNT($D$11:D16)=0,"",F16/E16) | H16: =IF(G16="","",IF(G16>=0.95,"En meta",IF(G16>=0.8,"Riesgo","Atrasado"))) | J16: =IF(I16="","",IF($I$9="","",IF($I$9=0,"",I16/$I$9))) | L16: =IF(K16="","",IF($K$9="","",IF($K$9=0,"",K16/$K$9))) | N16: =IF(M16="","",IF($M$9="","",IF($M$9=0,"",M16/$M$9))) | P16: =IF(O16="","",IF($O$9="","",IF($O$9=0,"",O16/$O$9))) | R16: =IF(Q16="","",IF($Q$9="","",IF($Q$9=0,"",Q16/$Q$9))) | T16: =IF(S16="","",IF($S$9="","",IF($S$9=0,"",S16/$S$9))) | V16: =IF(U16="","",IF($U$9="","",IF($U$9=0,"",U16/$U$9))) | X16: =IF(W16="","",IF($W$9="","",IF($W$9=0,"",W16/$W$9)))
A17: 7 | B17: 46230 | C17: =$B$5/$B$8 -> 0.12345679 | E17: =SUM($C$11:C17) -> 0.86419753 | F17: =SUM($D$11:D17) -> 0 | G17: =IF(COUNT($D$11:D17)=0,"",F17/E17) | H17: =IF(G17="","",IF(G17>=0.95,"En meta",IF(G17>=0.8,"Riesgo","Atrasado"))) | J17: =IF(I17="","",IF($I$9="","",IF($I$9=0,"",I17/$I$9))) | L17: =IF(K17="","",IF($K$9="","",IF($K$9=0,"",K17/$K$9))) | N17: =IF(M17="","",IF($M$9="","",IF($M$9=0,"",M17/$M$9))) | P17: =IF(O17="","",IF($O$9="","",IF($O$9=0,"",O17/$O$9))) | R17: =IF(Q17="","",IF($Q$9="","",IF($Q$9=0,"",Q17/$Q$9))) | T17: =IF(S17="","",IF($S$9="","",IF($S$9=0,"",S17/$S$9))) | V17: =IF(U17="","",IF($U$9="","",IF($U$9=0,"",U17/$U$9))) | X17: =IF(W17="","",IF($W$9="","",IF($W$9=0,"",W17/$W$9)))
A18: 8 | B18: 46237 | C18: =$B$5/$B$8 -> 0.12345679 | E18: =SUM($C$11:C18) -> 0.98765432 | F18: =SUM($D$11:D18) -> 0 | G18: =IF(COUNT($D$11:D18)=0,"",F18/E18) | H18: =IF(G18="","",IF(G18>=0.95,"En meta",IF(G18>=0.8,"Riesgo","Atrasado"))) | J18: =IF(I18="","",IF($I$9="","",IF($I$9=0,"",I18/$I$9))) | L18: =IF(K18="","",IF($K$9="","",IF($K$9=0,"",K18/$K$9))) | N18: =IF(M18="","",IF($M$9="","",IF($M$9=0,"",M18/$M$9))) | P18: =IF(O18="","",IF($O$9="","",IF($O$9=0,"",O18/$O$9))) | R18: =IF(Q18="","",IF($Q$9="","",IF($Q$9=0,"",Q18/$Q$9))) | T18: =IF(S18="","",IF($S$9="","",IF($S$9=0,"",S18/$S$9))) | V18: =IF(U18="","",IF($U$9="","",IF($U$9=0,"",U18/$U$9))) | X18: =IF(W18="","",IF($W$9="","",IF($W$9=0,"",W18/$W$9)))
A19: 9 | B19: 46244 | C19: =$B$5/$B$8 -> 0.12345679 | E19: =SUM($C$11:C19) -> 1.1111111 | F19: =SUM($D$11:D19) -> 0 | G19: =IF(COUNT($D$11:D19)=0,"",F19/E19) | H19: =IF(G19="","",IF(G19>=0.95,"En meta",IF(G19>=0.8,"Riesgo","Atrasado"))) | J19: =IF(I19="","",IF($I$9="","",IF($I$9=0,"",I19/$I$9))) | L19: =IF(K19="","",IF($K$9="","",IF($K$9=0,"",K19/$K$9))) | N19: =IF(M19="","",IF($M$9="","",IF($M$9=0,"",M19/$M$9))) | P19: =IF(O19="","",IF($O$9="","",IF($O$9=0,"",O19/$O$9))) | R19: =IF(Q19="","",IF($Q$9="","",IF($Q$9=0,"",Q19/$Q$9))) | T19: =IF(S19="","",IF($S$9="","",IF($S$9=0,"",S19/$S$9))) | V19: =IF(U19="","",IF($U$9="","",IF($U$9=0,"",U19/$U$9))) | X19: =IF(W19="","",IF($W$9="","",IF($W$9=0,"",W19/$W$9)))
A20: 10 | B20: 46251 | C20: =$B$5/$B$8 -> 0.12345679 | E20: =SUM($C$11:C20) -> 1.2345679 | F20: =SUM($D$11:D20) -> 0 | G20: =IF(COUNT($D$11:D20)=0,"",F20/E20) | H20: =IF(G20="","",IF(G20>=0.95,"En meta",IF(G20>=0.8,"Riesgo","Atrasado"))) | J20: =IF(I20="","",IF($I$9="","",IF($I$9=0,"",I20/$I$9))) | L20: =IF(K20="","",IF($K$9="","",IF($K$9=0,"",K20/$K$9))) | N20: =IF(M20="","",IF($M$9="","",IF($M$9=0,"",M20/$M$9))) | P20: =IF(O20="","",IF($O$9="","",IF($O$9=0,"",O20/$O$9))) | R20: =IF(Q20="","",IF($Q$9="","",IF($Q$9=0,"",Q20/$Q$9))) | T20: =IF(S20="","",IF($S$9="","",IF($S$9=0,"",S20/$S$9))) | V20: =IF(U20="","",IF($U$9="","",IF($U$9=0,"",U20/$U$9))) | X20: =IF(W20="","",IF($W$9="","",IF($W$9=0,"",W20/$W$9)))
A21: 11 | B21: 46258 | C21: =$B$5/$B$8 -> 0.12345679 | E21: =SUM($C$11:C21) -> 1.3580247 | F21: =SUM($D$11:D21) -> 0 | G21: =IF(COUNT($D$11:D21)=0,"",F21/E21) | H21: =IF(G21="","",IF(G21>=0.95,"En meta",IF(G21>=0.8,"Riesgo","Atrasado"))) | J21: =IF(I21="","",IF($I$9="","",IF($I$9=0,"",I21/$I$9))) | L21: =IF(K21="","",IF($K$9="","",IF($K$9=0,"",K21/$K$9))) | N21: =IF(M21="","",IF($M$9="","",IF($M$9=0,"",M21/$M$9))) | P21: =IF(O21="","",IF($O$9="","",IF($O$9=0,"",O21/$O$9))) | R21: =IF(Q21="","",IF($Q$9="","",IF($Q$9=0,"",Q21/$Q$9))) | T21: =IF(S21="","",IF($S$9="","",IF($S$9=0,"",S21/$S$9))) | V21: =IF(U21="","",IF($U$9="","",IF($U$9=0,"",U21/$U$9))) | X21: =IF(W21="","",IF($W$9="","",IF($W$9=0,"",W21/$W$9)))
A22: 12 | B22: 46265 | C22: =$B$5/$B$8 -> 0.12345679 | E22: =SUM($C$11:C22) -> 1.4814815 | F22: =SUM($D$11:D22) -> 0 | G22: =IF(COUNT($D$11:D22)=0,"",F22/E22) | H22: =IF(G22="","",IF(G22>=0.95,"En meta",IF(G22>=0.8,"Riesgo","Atrasado"))) | J22: =IF(I22="","",IF($I$9="","",IF($I$9=0,"",I22/$I$9))) | L22: =IF(K22="","",IF($K$9="","",IF($K$9=0,"",K22/$K$9))) | N22: =IF(M22="","",IF($M$9="","",IF($M$9=0,"",M22/$M$9))) | P22: =IF(O22="","",IF($O$9="","",IF($O$9=0,"",O22/$O$9))) | R22: =IF(Q22="","",IF($Q$9="","",IF($Q$9=0,"",Q22/$Q$9))) | T22: =IF(S22="","",IF($S$9="","",IF($S$9=0,"",S22/$S$9))) | V22: =IF(U22="","",IF($U$9="","",IF($U$9=0,"",U22/$U$9))) | X22: =IF(W22="","",IF($W$9="","",IF($W$9=0,"",W22/$W$9)))
... A91: 81 | B91: 46748 | C91: =$B$5/$B$8 -> 0.12345679 | E91: =SUM($C$11:C91) -> 10 | F91: =SUM($D$11:D91) -> 0 | G91: =IF(COUNT($D$11:D91)=0,"",F91/E91) | H91: =IF(G91="","",IF(G91>=0.95,"En meta",IF(G91>=0.8,"Riesgo","Atrasado"))) | J91: =IF(I91="","",IF($I$9="","",IF($I$9=0,"",I91/$I$9))) | L91: =IF(K91="","",IF($K$9="","",IF($K$9=0,"",K91/$K$9))) | N91: =IF(M91="","",IF($M$9="","",IF($M$9=0,"",M91/$M$9))) | P91: =IF(O91="","",IF($O$9="","",IF($O$9=0,"",O91/$O$9))) | R91: =IF(Q91="","",IF($Q$9="","",IF($Q$9=0,"",Q91/$Q$9))) | T91: =IF(S91="","",IF($S$9="","",IF($S$9=0,"",S91/$S$9))) | V91: =IF(U91="","",IF($U$9="","",IF($U$9=0,"",U91/$U$9))) | X91: =IF(W91="","",IF($W$9="","",IF($W$9=0,"",W91/$W$9)))

Sheet 4. Entregas 100%
A1: WIG 4 — Cumplir el 100% de entregas y colocaciones en tiempo y forma
A2: Indicador lag: | B2: % de colocaciones y entregas de la semana realizadas en tiempo y forma.
A3: De X a Y: | B3: Sostener 100% de cumplimiento semanal durante todo el periodo.
A4: Dueño: | B4: Por asignar | D4: Equipo: | E4: Finanzas
A5: Meta: | B5: 1 | D5: Inicio: | E5: 46188 | G5: Fin: | H5: 46748
A6: Leads: | B6: Hasta 8 indicadores predictivos a la derecha. L1–L2 = apuesta principal del equipo; L3–L8 = indicadores de apoyo. Nombre (fila 8) y meta semanal (fila 9) editables en azul.
A8: Periodos: | B8: =COUNT(A11:A91) -> 81 | H8: Lead → | I8: L1. % entregas programadas con checklist completo | K8: L2. Riesgos de entrega escalados ≥1 semana antes | M8: L3. % órdenes de compra liberadas a tiempo | O8: L4. % inventario confirmado ≥5 días antes | Q8: L5. Coordinaciones logísticas confirmadas | S8: L6. % facturas emitidas ≤48h tras la entrega | U8: (Disponible) | W8: (Disponible)
A9: Celdas azules = se digitan cada lunes. Celdas negras = fórmulas, no tocar. | H9: Meta → | I9: 1 | K9: 1 | M9: 1 | O9: 1 | Q9: 5 | S9: 1
A10: # | B10: Semana | C10: Meta | D10: Real | G10: Brecha vs meta | H10: Estado | I10: Real | J10: % | K10: Real | L10: % | M10: Real | N10: % | O10: Real | P10: % | Q10: Real | R10: % | S10: Real | T10: % | U10: Real | V10: % | W10: Real | X10: %
A11: 1 | B11: 46188 | C11: =$B$5 -> 1 | G11: =IF(D11="","",D11-C11) | H11: =IF(D11="","",IF(D11>=C11,"En meta",IF(D11>=C11-0.05,"Riesgo","Atrasado"))) | J11: =IF(I11="","",IF($I$9="","",IF($I$9=0,"",I11/$I$9))) | L11: =IF(K11="","",IF($K$9="","",IF($K$9=0,"",K11/$K$9))) | N11: =IF(M11="","",IF($M$9="","",IF($M$9=0,"",M11/$M$9))) | P11: =IF(O11="","",IF($O$9="","",IF($O$9=0,"",O11/$O$9))) | R11: =IF(Q11="","",IF($Q$9="","",IF($Q$9=0,"",Q11/$Q$9))) | T11: =IF(S11="","",IF($S$9="","",IF($S$9=0,"",S11/$S$9))) | V11: =IF(U11="","",IF($U$9="","",IF($U$9=0,"",U11/$U$9))) | X11: =IF(W11="","",IF($W$9="","",IF($W$9=0,"",W11/$W$9)))
A12: 2 | B12: 46195 | C12: =$B$5 -> 1 | G12: =IF(D12="","",D12-C12) | H12: =IF(D12="","",IF(D12>=C12,"En meta",IF(D12>=C12-0.05,"Riesgo","Atrasado"))) | J12: =IF(I12="","",IF($I$9="","",IF($I$9=0,"",I12/$I$9))) | L12: =IF(K12="","",IF($K$9="","",IF($K$9=0,"",K12/$K$9))) | N12: =IF(M12="","",IF($M$9="","",IF($M$9=0,"",M12/$M$9))) | P12: =IF(O12="","",IF($O$9="","",IF($O$9=0,"",O12/$O$9))) | R12: =IF(Q12="","",IF($Q$9="","",IF($Q$9=0,"",Q12/$Q$9))) | T12: =IF(S12="","",IF($S$9="","",IF($S$9=0,"",S12/$S$9))) | V12: =IF(U12="","",IF($U$9="","",IF($U$9=0,"",U12/$U$9))) | X12: =IF(W12="","",IF($W$9="","",IF($W$9=0,"",W12/$W$9)))
A13: 3 | B13: 46202 | C13: =$B$5 -> 1 | G13: =IF(D13="","",D13-C13) | H13: =IF(D13="","",IF(D13>=C13,"En meta",IF(D13>=C13-0.05,"Riesgo","Atrasado"))) | J13: =IF(I13="","",IF($I$9="","",IF($I$9=0,"",I13/$I$9))) | L13: =IF(K13="","",IF($K$9="","",IF($K$9=0,"",K13/$K$9))) | N13: =IF(M13="","",IF($M$9="","",IF($M$9=0,"",M13/$M$9))) | P13: =IF(O13="","",IF($O$9="","",IF($O$9=0,"",O13/$O$9))) | R13: =IF(Q13="","",IF($Q$9="","",IF($Q$9=0,"",Q13/$Q$9))) | T13: =IF(S13="","",IF($S$9="","",IF($S$9=0,"",S13/$S$9))) | V13: =IF(U13="","",IF($U$9="","",IF($U$9=0,"",U13/$U$9))) | X13: =IF(W13="","",IF($W$9="","",IF($W$9=0,"",W13/$W$9)))
A14: 4 | B14: 46209 | C14: =$B$5 -> 1 | G14: =IF(D14="","",D14-C14) | H14: =IF(D14="","",IF(D14>=C14,"En meta",IF(D14>=C14-0.05,"Riesgo","Atrasado"))) | J14: =IF(I14="","",IF($I$9="","",IF($I$9=0,"",I14/$I$9))) | L14: =IF(K14="","",IF($K$9="","",IF($K$9=0,"",K14/$K$9))) | N14: =IF(M14="","",IF($M$9="","",IF($M$9=0,"",M14/$M$9))) | P14: =IF(O14="","",IF($O$9="","",IF($O$9=0,"",O14/$O$9))) | R14: =IF(Q14="","",IF($Q$9="","",IF($Q$9=0,"",Q14/$Q$9))) | T14: =IF(S14="","",IF($S$9="","",IF($S$9=0,"",S14/$S$9))) | V14: =IF(U14="","",IF($U$9="","",IF($U$9=0,"",U14/$U$9))) | X14: =IF(W14="","",IF($W$9="","",IF($W$9=0,"",W14/$W$9)))
A15: 5 | B15: 46216 | C15: =$B$5 -> 1 | G15: =IF(D15="","",D15-C15) | H15: =IF(D15="","",IF(D15>=C15,"En meta",IF(D15>=C15-0.05,"Riesgo","Atrasado"))) | J15: =IF(I15="","",IF($I$9="","",IF($I$9=0,"",I15/$I$9))) | L15: =IF(K15="","",IF($K$9="","",IF($K$9=0,"",K15/$K$9))) | N15: =IF(M15="","",IF($M$9="","",IF($M$9=0,"",M15/$M$9))) | P15: =IF(O15="","",IF($O$9="","",IF($O$9=0,"",O15/$O$9))) | R15: =IF(Q15="","",IF($Q$9="","",IF($Q$9=0,"",Q15/$Q$9))) | T15: =IF(S15="","",IF($S$9="","",IF($S$9=0,"",S15/$S$9))) | V15: =IF(U15="","",IF($U$9="","",IF($U$9=0,"",U15/$U$9))) | X15: =IF(W15="","",IF($W$9="","",IF($W$9=0,"",W15/$W$9)))
A16: 6 | B16: 46223 | C16: =$B$5 -> 1 | G16: =IF(D16="","",D16-C16) | H16: =IF(D16="","",IF(D16>=C16,"En meta",IF(D16>=C16-0.05,"Riesgo","Atrasado"))) | J16: =IF(I16="","",IF($I$9="","",IF($I$9=0,"",I16/$I$9))) | L16: =IF(K16="","",IF($K$9="","",IF($K$9=0,"",K16/$K$9))) | N16: =IF(M16="","",IF($M$9="","",IF($M$9=0,"",M16/$M$9))) | P16: =IF(O16="","",IF($O$9="","",IF($O$9=0,"",O16/$O$9))) | R16: =IF(Q16="","",IF($Q$9="","",IF($Q$9=0,"",Q16/$Q$9))) | T16: =IF(S16="","",IF($S$9="","",IF($S$9=0,"",S16/$S$9))) | V16: =IF(U16="","",IF($U$9="","",IF($U$9=0,"",U16/$U$9))) | X16: =IF(W16="","",IF($W$9="","",IF($W$9=0,"",W16/$W$9)))
A17: 7 | B17: 46230 | C17: =$B$5 -> 1 | G17: =IF(D17="","",D17-C17) | H17: =IF(D17="","",IF(D17>=C17,"En meta",IF(D17>=C17-0.05,"Riesgo","Atrasado"))) | J17: =IF(I17="","",IF($I$9="","",IF($I$9=0,"",I17/$I$9))) | L17: =IF(K17="","",IF($K$9="","",IF($K$9=0,"",K17/$K$9))) | N17: =IF(M17="","",IF($M$9="","",IF($M$9=0,"",M17/$M$9))) | P17: =IF(O17="","",IF($O$9="","",IF($O$9=0,"",O17/$O$9))) | R17: =IF(Q17="","",IF($Q$9="","",IF($Q$9=0,"",Q17/$Q$9))) | T17: =IF(S17="","",IF($S$9="","",IF($S$9=0,"",S17/$S$9))) | V17: =IF(U17="","",IF($U$9="","",IF($U$9=0,"",U17/$U$9))) | X17: =IF(W17="","",IF($W$9="","",IF($W$9=0,"",W17/$W$9)))
A18: 8 | B18: 46237 | C18: =$B$5 -> 1 | G18: =IF(D18="","",D18-C18) | H18: =IF(D18="","",IF(D18>=C18,"En meta",IF(D18>=C18-0.05,"Riesgo","Atrasado"))) | J18: =IF(I18="","",IF($I$9="","",IF($I$9=0,"",I18/$I$9))) | L18: =IF(K18="","",IF($K$9="","",IF($K$9=0,"",K18/$K$9))) | N18: =IF(M18="","",IF($M$9="","",IF($M$9=0,"",M18/$M$9))) | P18: =IF(O18="","",IF($O$9="","",IF($O$9=0,"",O18/$O$9))) | R18: =IF(Q18="","",IF($Q$9="","",IF($Q$9=0,"",Q18/$Q$9))) | T18: =IF(S18="","",IF($S$9="","",IF($S$9=0,"",S18/$S$9))) | V18: =IF(U18="","",IF($U$9="","",IF($U$9=0,"",U18/$U$9))) | X18: =IF(W18="","",IF($W$9="","",IF($W$9=0,"",W18/$W$9)))
A19: 9 | B19: 46244 | C19: =$B$5 -> 1 | G19: =IF(D19="","",D19-C19) | H19: =IF(D19="","",IF(D19>=C19,"En meta",IF(D19>=C19-0.05,"Riesgo","Atrasado"))) | J19: =IF(I19="","",IF($I$9="","",IF($I$9=0,"",I19/$I$9))) | L19: =IF(K19="","",IF($K$9="","",IF($K$9=0,"",K19/$K$9))) | N19: =IF(M19="","",IF($M$9="","",IF($M$9=0,"",M19/$M$9))) | P19: =IF(O19="","",IF($O$9="","",IF($O$9=0,"",O19/$O$9))) | R19: =IF(Q19="","",IF($Q$9="","",IF($Q$9=0,"",Q19/$Q$9))) | T19: =IF(S19="","",IF($S$9="","",IF($S$9=0,"",S19/$S$9))) | V19: =IF(U19="","",IF($U$9="","",IF($U$9=0,"",U19/$U$9))) | X19: =IF(W19="","",IF($W$9="","",IF($W$9=0,"",W19/$W$9)))
A20: 10 | B20: 46251 | C20: =$B$5 -> 1 | G20: =IF(D20="","",D20-C20) | H20: =IF(D20="","",IF(D20>=C20,"En meta",IF(D20>=C20-0.05,"Riesgo","Atrasado"))) | J20: =IF(I20="","",IF($I$9="","",IF($I$9=0,"",I20/$I$9))) | L20: =IF(K20="","",IF($K$9="","",IF($K$9=0,"",K20/$K$9))) | N20: =IF(M20="","",IF($M$9="","",IF($M$9=0,"",M20/$M$9))) | P20: =IF(O20="","",IF($O$9="","",IF($O$9=0,"",O20/$O$9))) | R20: =IF(Q20="","",IF($Q$9="","",IF($Q$9=0,"",Q20/$Q$9))) | T20: =IF(S20="","",IF($S$9="","",IF($S$9=0,"",S20/$S$9))) | V20: =IF(U20="","",IF($U$9="","",IF($U$9=0,"",U20/$U$9))) | X20: =IF(W20="","",IF($W$9="","",IF($W$9=0,"",W20/$W$9)))
A21: 11 | B21: 46258 | C21: =$B$5 -> 1 | G21: =IF(D21="","",D21-C21) | H21: =IF(D21="","",IF(D21>=C21,"En meta",IF(D21>=C21-0.05,"Riesgo","Atrasado"))) | J21: =IF(I21="","",IF($I$9="","",IF($I$9=0,"",I21/$I$9))) | L21: =IF(K21="","",IF($K$9="","",IF($K$9=0,"",K21/$K$9))) | N21: =IF(M21="","",IF($M$9="","",IF($M$9=0,"",M21/$M$9))) | P21: =IF(O21="","",IF($O$9="","",IF($O$9=0,"",O21/$O$9))) | R21: =IF(Q21="","",IF($Q$9="","",IF($Q$9=0,"",Q21/$Q$9))) | T21: =IF(S21="","",IF($S$9="","",IF($S$9=0,"",S21/$S$9))) | V21: =IF(U21="","",IF($U$9="","",IF($U$9=0,"",U21/$U$9))) | X21: =IF(W21="","",IF($W$9="","",IF($W$9=0,"",W21/$W$9)))
A22: 12 | B22: 46265 | C22: =$B$5 -> 1 | G22: =IF(D22="","",D22-C22) | H22: =IF(D22="","",IF(D22>=C22,"En meta",IF(D22>=C22-0.05,"Riesgo","Atrasado"))) | J22: =IF(I22="","",IF($I$9="","",IF($I$9=0,"",I22/$I$9))) | L22: =IF(K22="","",IF($K$9="","",IF($K$9=0,"",K22/$K$9))) | N22: =IF(M22="","",IF($M$9="","",IF($M$9=0,"",M22/$M$9))) | P22: =IF(O22="","",IF($O$9="","",IF($O$9=0,"",O22/$O$9))) | R22: =IF(Q22="","",IF($Q$9="","",IF($Q$9=0,"",Q22/$Q$9))) | T22: =IF(S22="","",IF($S$9="","",IF($S$9=0,"",S22/$S$9))) | V22: =IF(U22="","",IF($U$9="","",IF($U$9=0,"",U22/$U$9))) | X22: =IF(W22="","",IF($W$9="","",IF($W$9=0,"",W22/$W$9)))
... A91: 81 | B91: 46748 | C91: =$B$5 -> 1 | G91: =IF(D91="","",D91-C91) | H91: =IF(D91="","",IF(D91>=C91,"En meta",IF(D91>=C91-0.05,"Riesgo","Atrasado"))) | J91: =IF(I91="","",IF($I$9="","",IF($I$9=0,"",I91/$I$9))) | L91: =IF(K91="","",IF($K$9="","",IF($K$9=0,"",K91/$K$9))) | N91: =IF(M91="","",IF($M$9="","",IF($M$9=0,"",M91/$M$9))) | P91: =IF(O91="","",IF($O$9="","",IF($O$9=0,"",O91/$O$9))) | R91: =IF(Q91="","",IF($Q$9="","",IF($Q$9=0,"",Q91/$Q$9))) | T91: =IF(S91="","",IF($S$9="","",IF($S$9=0,"",S91/$S$9))) | V91: =IF(U91="","",IF($U$9="","",IF($U$9=0,"",U91/$U$9))) | X91: =IF(W91="","",IF($W$9="","",IF($W$9=0,"",W91/$W$9)))

Sheet 5. MV Datacenter
A1: WIG 5 — Incrementar el MV de servicios basados en el DC GBM San Marcos en $20,000
A2: Indicador lag: | B2: MV nuevo firmado de servicios basados desde el datacenter (USD acumulado).
A3: De X a Y: | B3: De $0 a +$20,000 de MV incremental, antes del 31 de diciembre de 2027.
A4: Dueño: | B4: Por asignar | D4: Equipo: | E4: Pre-Sales, Del - DC
A5: Meta: | B5: 20000 | D5: Inicio: | E5: 46188 | G5: Fin: | H5: 46748
A6: Leads: | B6: Hasta 8 indicadores predictivos a la derecha. L1–L2 = apuesta principal del equipo; L3–L8 = indicadores de apoyo. Nombre (fila 8) y meta semanal (fila 9) editables en azul.
A8: Periodos: | B8: =COUNT(A11:A91) -> 81 | H8: Lead → | I8: L1. Propuestas de servicios DC presentadas | K8: L2. Workloads nuevos aprovisionados / migrados | M8: L3. Assessments de migración realizados | O8: L4. Opps DC activas en pipeline | Q8: L5. Clientes contactados con oferta DC | S8: L6. % capacidad DC documentada y actualizada | U8: (Disponible) | W8: (Disponible)
A9: Celdas azules = se digitan cada lunes. Celdas negras = fórmulas, no tocar. | H9: Meta → | I9: 2 | K9: 1 | M9: 1 | O9: 4 | Q9: 3 | S9: 1
A10: # | B10: Semana | C10: Meta semana | D10: Real | E10: Meta acum. | F10: Real acum. | G10: % avance | H10: Estado | I10: Real | J10: % | K10: Real | L10: % | M10: Real | N10: % | O10: Real | P10: % | Q10: Real | R10: % | S10: Real | T10: % | U10: Real | V10: % | W10: Real | X10: %
A11: 1 | B11: 46188 | C11: =$B$5/$B$8 -> 246.91358 | E11: =SUM($C$11:C11) -> 246.91358 | F11: =SUM($D$11:D11) -> 0 | G11: =IF(COUNT($D$11:D11)=0,"",F11/E11) | H11: =IF(G11="","",IF(G11>=0.95,"En meta",IF(G11>=0.8,"Riesgo","Atrasado"))) | J11: =IF(I11="","",IF($I$9="","",IF($I$9=0,"",I11/$I$9))) | L11: =IF(K11="","",IF($K$9="","",IF($K$9=0,"",K11/$K$9))) | N11: =IF(M11="","",IF($M$9="","",IF($M$9=0,"",M11/$M$9))) | P11: =IF(O11="","",IF($O$9="","",IF($O$9=0,"",O11/$O$9))) | R11: =IF(Q11="","",IF($Q$9="","",IF($Q$9=0,"",Q11/$Q$9))) | T11: =IF(S11="","",IF($S$9="","",IF($S$9=0,"",S11/$S$9))) | V11: =IF(U11="","",IF($U$9="","",IF($U$9=0,"",U11/$U$9))) | X11: =IF(W11="","",IF($W$9="","",IF($W$9=0,"",W11/$W$9)))
A12: 2 | B12: 46195 | C12: =$B$5/$B$8 -> 246.91358 | E12: =SUM($C$11:C12) -> 493.82716 | F12: =SUM($D$11:D12) -> 0 | G12: =IF(COUNT($D$11:D12)=0,"",F12/E12) | H12: =IF(G12="","",IF(G12>=0.95,"En meta",IF(G12>=0.8,"Riesgo","Atrasado"))) | J12: =IF(I12="","",IF($I$9="","",IF($I$9=0,"",I12/$I$9))) | L12: =IF(K12="","",IF($K$9="","",IF($K$9=0,"",K12/$K$9))) | N12: =IF(M12="","",IF($M$9="","",IF($M$9=0,"",M12/$M$9))) | P12: =IF(O12="","",IF($O$9="","",IF($O$9=0,"",O12/$O$9))) | R12: =IF(Q12="","",IF($Q$9="","",IF($Q$9=0,"",Q12/$Q$9))) | T12: =IF(S12="","",IF($S$9="","",IF($S$9=0,"",S12/$S$9))) | V12: =IF(U12="","",IF($U$9="","",IF($U$9=0,"",U12/$U$9))) | X12: =IF(W12="","",IF($W$9="","",IF($W$9=0,"",W12/$W$9)))
A13: 3 | B13: 46202 | C13: =$B$5/$B$8 -> 246.91358 | E13: =SUM($C$11:C13) -> 740.74074 | F13: =SUM($D$11:D13) -> 0 | G13: =IF(COUNT($D$11:D13)=0,"",F13/E13) | H13: =IF(G13="","",IF(G13>=0.95,"En meta",IF(G13>=0.8,"Riesgo","Atrasado"))) | J13: =IF(I13="","",IF($I$9="","",IF($I$9=0,"",I13/$I$9))) | L13: =IF(K13="","",IF($K$9="","",IF($K$9=0,"",K13/$K$9))) | N13: =IF(M13="","",IF($M$9="","",IF($M$9=0,"",M13/$M$9))) | P13: =IF(O13="","",IF($O$9="","",IF($O$9=0,"",O13/$O$9))) | R13: =IF(Q13="","",IF($Q$9="","",IF($Q$9=0,"",Q13/$Q$9))) | T13: =IF(S13="","",IF($S$9="","",IF($S$9=0,"",S13/$S$9))) | V13: =IF(U13="","",IF($U$9="","",IF($U$9=0,"",U13/$U$9))) | X13: =IF(W13="","",IF($W$9="","",IF($W$9=0,"",W13/$W$9)))
A14: 4 | B14: 46209 | C14: =$B$5/$B$8 -> 246.91358 | E14: =SUM($C$11:C14) -> 987.65432 | F14: =SUM($D$11:D14) -> 0 | G14: =IF(COUNT($D$11:D14)=0,"",F14/E14) | H14: =IF(G14="","",IF(G14>=0.95,"En meta",IF(G14>=0.8,"Riesgo","Atrasado"))) | J14: =IF(I14="","",IF($I$9="","",IF($I$9=0,"",I14/$I$9))) | L14: =IF(K14="","",IF($K$9="","",IF($K$9=0,"",K14/$K$9))) | N14: =IF(M14="","",IF($M$9="","",IF($M$9=0,"",M14/$M$9))) | P14: =IF(O14="","",IF($O$9="","",IF($O$9=0,"",O14/$O$9))) | R14: =IF(Q14="","",IF($Q$9="","",IF($Q$9=0,"",Q14/$Q$9))) | T14: =IF(S14="","",IF($S$9="","",IF($S$9=0,"",S14/$S$9))) | V14: =IF(U14="","",IF($U$9="","",IF($U$9=0,"",U14/$U$9))) | X14: =IF(W14="","",IF($W$9="","",IF($W$9=0,"",W14/$W$9)))
A15: 5 | B15: 46216 | C15: =$B$5/$B$8 -> 246.91358 | E15: =SUM($C$11:C15) -> 1234.5679 | F15: =SUM($D$11:D15) -> 0 | G15: =IF(COUNT($D$11:D15)=0,"",F15/E15) | H15: =IF(G15="","",IF(G15>=0.95,"En meta",IF(G15>=0.8,"Riesgo","Atrasado"))) | J15: =IF(I15="","",IF($I$9="","",IF($I$9=0,"",I15/$I$9))) | L15: =IF(K15="","",IF($K$9="","",IF($K$9=0,"",K15/$K$9))) | N15: =IF(M15="","",IF($M$9="","",IF($M$9=0,"",M15/$M$9))) | P15: =IF(O15="","",IF($O$9="","",IF($O$9=0,"",O15/$O$9))) | R15: =IF(Q15="","",IF($Q$9="","",IF($Q$9=0,"",Q15/$Q$9))) | T15: =IF(S15="","",IF($S$9="","",IF($S$9=0,"",S15/$S$9))) | V15: =IF(U15="","",IF($U$9="","",IF($U$9=0,"",U15/$U$9))) | X15: =IF(W15="","",IF($W$9="","",IF($W$9=0,"",W15/$W$9)))
A16: 6 | B16: 46223 | C16: =$B$5/$B$8 -> 246.91358 | E16: =SUM($C$11:C16) -> 1481.4815 | F16: =SUM($D$11:D16) -> 0 | G16: =IF(COUNT($D$11:D16)=0,"",F16/E16) | H16: =IF(G16="","",IF(G16>=0.95,"En meta",IF(G16>=0.8,"Riesgo","Atrasado"))) | J16: =IF(I16="","",IF($I$9="","",IF($I$9=0,"",I16/$I$9))) | L16: =IF(K16="","",IF($K$9="","",IF($K$9=0,"",K16/$K$9))) | N16: =IF(M16="","",IF($M$9="","",IF($M$9=0,"",M16/$M$9))) | P16: =IF(O16="","",IF($O$9="","",IF($O$9=0,"",O16/$O$9))) | R16: =IF(Q16="","",IF($Q$9="","",IF($Q$9=0,"",Q16/$Q$9))) | T16: =IF(S16="","",IF($S$9="","",IF($S$9=0,"",S16/$S$9))) | V16: =IF(U16="","",IF($U$9="","",IF($U$9=0,"",U16/$U$9))) | X16: =IF(W16="","",IF($W$9="","",IF($W$9=0,"",W16/$W$9)))
A17: 7 | B17: 46230 | C17: =$B$5/$B$8 -> 246.91358 | E17: =SUM($C$11:C17) -> 1728.3951 | F17: =SUM($D$11:D17) -> 0 | G17: =IF(COUNT($D$11:D17)=0,"",F17/E17) | H17: =IF(G17="","",IF(G17>=0.95,"En meta",IF(G17>=0.8,"Riesgo","Atrasado"))) | J17: =IF(I17="","",IF($I$9="","",IF($I$9=0,"",I17/$I$9))) | L17: =IF(K17="","",IF($K$9="","",IF($K$9=0,"",K17/$K$9))) | N17: =IF(M17="","",IF($M$9="","",IF($M$9=0,"",M17/$M$9))) | P17: =IF(O17="","",IF($O$9="","",IF($O$9=0,"",O17/$O$9))) | R17: =IF(Q17="","",IF($Q$9="","",IF($Q$9=0,"",Q17/$Q$9))) | T17: =IF(S17="","",IF($S$9="","",IF($S$9=0,"",S17/$S$9))) | V17: =IF(U17="","",IF($U$9="","",IF($U$9=0,"",U17/$U$9))) | X17: =IF(W17="","",IF($W$9="","",IF($W$9=0,"",W17/$W$9)))
A18: 8 | B18: 46237 | C18: =$B$5/$B$8 -> 246.91358 | E18: =SUM($C$11:C18) -> 1975.3086 | F18: =SUM($D$11:D18) -> 0 | G18: =IF(COUNT($D$11:D18)=0,"",F18/E18) | H18: =IF(G18="","",IF(G18>=0.95,"En meta",IF(G18>=0.8,"Riesgo","Atrasado"))) | J18: =IF(I18="","",IF($I$9="","",IF($I$9=0,"",I18/$I$9))) | L18: =IF(K18="","",IF($K$9="","",IF($K$9=0,"",K18/$K$9))) | N18: =IF(M18="","",IF($M$9="","",IF($M$9=0,"",M18/$M$9))) | P18: =IF(O18="","",IF($O$9="","",IF($O$9=0,"",O18/$O$9))) | R18: =IF(Q18="","",IF($Q$9="","",IF($Q$9=0,"",Q18/$Q$9))) | T18: =IF(S18="","",IF($S$9="","",IF($S$9=0,"",S18/$S$9))) | V18: =IF(U18="","",IF($U$9="","",IF($U$9=0,"",U18/$U$9))) | X18: =IF(W18="","",IF($W$9="","",IF($W$9=0,"",W18/$W$9)))
A19: 9 | B19: 46244 | C19: =$B$5/$B$8 -> 246.91358 | E19: =SUM($C$11:C19) -> 2222.2222 | F19: =SUM($D$11:D19) -> 0 | G19: =IF(COUNT($D$11:D19)=0,"",F19/E19) | H19: =IF(G19="","",IF(G19>=0.95,"En meta",IF(G19>=0.8,"Riesgo","Atrasado"))) | J19: =IF(I19="","",IF($I$9="","",IF($I$9=0,"",I19/$I$9))) | L19: =IF(K19="","",IF($K$9="","",IF($K$9=0,"",K19/$K$9))) | N19: =IF(M19="","",IF($M$9="","",IF($M$9=0,"",M19/$M$9))) | P19: =IF(O19="","",IF($O$9="","",IF($O$9=0,"",O19/$O$9))) | R19: =IF(Q19="","",IF($Q$9="","",IF($Q$9=0,"",Q19/$Q$9))) | T19: =IF(S19="","",IF($S$9="","",IF($S$9=0,"",S19/$S$9))) | V19: =IF(U19="","",IF($U$9="","",IF($U$9=0,"",U19/$U$9))) | X19: =IF(W19="","",IF($W$9="","",IF($W$9=0,"",W19/$W$9)))
A20: 10 | B20: 46251 | C20: =$B$5/$B$8 -> 246.91358 | E20: =SUM($C$11:C20) -> 2469.1358 | F20: =SUM($D$11:D20) -> 0 | G20: =IF(COUNT($D$11:D20)=0,"",F20/E20) | H20: =IF(G20="","",IF(G20>=0.95,"En meta",IF(G20>=0.8,"Riesgo","Atrasado"))) | J20: =IF(I20="","",IF($I$9="","",IF($I$9=0,"",I20/$I$9))) | L20: =IF(K20="","",IF($K$9="","",IF($K$9=0,"",K20/$K$9))) | N20: =IF(M20="","",IF($M$9="","",IF($M$9=0,"",M20/$M$9))) | P20: =IF(O20="","",IF($O$9="","",IF($O$9=0,"",O20/$O$9))) | R20: =IF(Q20="","",IF($Q$9="","",IF($Q$9=0,"",Q20/$Q$9))) | T20: =IF(S20="","",IF($S$9="","",IF($S$9=0,"",S20/$S$9))) | V20: =IF(U20="","",IF($U$9="","",IF($U$9=0,"",U20/$U$9))) | X20: =IF(W20="","",IF($W$9="","",IF($W$9=0,"",W20/$W$9)))
