Workbook

Sheet Dashboard
A1: Tablero 4DX — GBM Nicaragua
A2: WIG de la compañía: Generar $1,000,000 de utilidad neta después de impuestos (NAT) en el 2027
A4: Meta anual NAT: | C4: 1000000
A6: Mes | B6: Meta mensual | C6: NAT real | D6: Meta acum. | E6: Real acum. | F6: % avance | G6: Estado
A7: 46388 | B7: =$C$4/12 -> 83333.333 | D7: =SUM($B$7:B7) -> 83333.333 | E7: =SUM($C$7:C7) -> 0 | F7: =IF(COUNT($C$7:C7)=0,"",E7/D7) | G7: =IF(F7="","",IF(F7>=0.95,"En meta",IF(F7>=0.8,"Riesgo","Atrasado")))
A8: 46419 | B8: =$C$4/12 -> 83333.333 | D8: =SUM($B$7:B8) -> 166666.67 | E8: =SUM($C$7:C8) -> 0 | F8: =IF(COUNT($C$7:C8)=0,"",E8/D8) | G8: =IF(F8="","",IF(F8>=0.95,"En meta",IF(F8>=0.8,"Riesgo","Atrasado")))
A9: 46447 | B9: =$C$4/12 -> 83333.333 | D9: =SUM($B$7:B9) -> 250000 | E9: =SUM($C$7:C9) -> 0 | F9: =IF(COUNT($C$7:C9)=0,"",E9/D9) | G9: =IF(F9="","",IF(F9>=0.95,"En meta",IF(F9>=0.8,"Riesgo","Atrasado")))
A10: 46478 | B10: =$C$4/12 -> 83333.333 | D10: =SUM($B$7:B10) -> 333333.33 | E10: =SUM($C$7:C10) -> 0 | F10: =IF(COUNT($C$7:C10)=0,"",E10/D10) | G10: =IF(F10="","",IF(F10>=0.95,"En meta",IF(F10>=0.8,"Riesgo","Atrasado")))
A11: 46508 | B11: =$C$4/12 -> 83333.333 | D11: =SUM($B$7:B11) -> 416666.67 | E11: =SUM($C$7:C11) -> 0 | F11: =IF(COUNT($C$7:C11)=0,"",E11/D11) | G11: =IF(F11="","",IF(F11>=0.95,"En meta",IF(F11>=0.8,"Riesgo","Atrasado")))
A12: 46539 | B12: =$C$4/12 -> 83333.333 | D12: =SUM($B$7:B12) -> 500000 | E12: =SUM($C$7:C12) -> 0 | F12: =IF(COUNT($C$7:C12)=0,"",E12/D12) | G12: =IF(F12="","",IF(F12>=0.95,"En meta",IF(F12>=0.8,"Riesgo","Atrasado")))
A13: 46569 | B13: =$C$4/12 -> 83333.333 | D13: =SUM($B$7:B13) -> 583333.33 | E13: =SUM($C$7:C13) -> 0 | F13: =IF(COUNT($C$7:C13)=0,"",E13/D13) | G13: =IF(F13="","",IF(F13>=0.95,"En meta",IF(F13>=0.8,"Riesgo","Atrasado")))
A14: 46600 | B14: =$C$4/12 -> 83333.333 | D14: =SUM($B$7:B14) -> 666666.67 | E14: =SUM($C$7:C14) -> 0 | F14: =IF(COUNT($C$7:C14)=0,"",E14/D14) | G14: =IF(F14="","",IF(F14>=0.95,"En meta",IF(F14>=0.8,"Riesgo","Atrasado")))
A15: 46631 | B15: =$C$4/12 -> 83333.333 | D15: =SUM($B$7:B15) -> 750000 | E15: =SUM($C$7:C15) -> 0 | F15: =IF(COUNT($C$7:C15)=0,"",E15/D15) | G15: =IF(F15="","",IF(F15>=0.95,"En meta",IF(F15>=0.8,"Riesgo","Atrasado")))
A16: 46661 | B16: =$C$4/12 -> 83333.333 | D16: =SUM($B$7:B16) -> 833333.33 | E16: =SUM($C$7:C16) -> 0 | F16: =IF(COUNT($C$7:C16)=0,"",E16/D16) | G16: =IF(F16="","",IF(F16>=0.95,"En meta",IF(F16>=0.8,"Riesgo","Atrasado")))
A17: 46692 | B17: =$C$4/12 -> 83333.333 | D17: =SUM($B$7:B17) -> 916666.67 | E17: =SUM($C$7:C17) -> 0 | F17: =IF(COUNT($C$7:C17)=0,"",E17/D17) | G17: =IF(F17="","",IF(F17>=0.95,"En meta",IF(F17>=0.8,"Riesgo","Atrasado")))
A18: 46722 | B18: =$C$4/12 -> 83333.333 | D18: =SUM($B$7:B18) -> 1000000 | E18: =SUM($C$7:C18) -> 0 | F18: =IF(COUNT($C$7:C18)=0,"",E18/D18) | G18: =IF(F18="","",IF(F18>=0.95,"En meta",IF(F18>=0.8,"Riesgo","Atrasado")))
A21: WIGs de soporte — estado al último dato ingresado
A22: # | B22: WIG de soporte | C22: Dueño | D22: Equipo | E22: Meta | F22: Último real | G22: Estado | H22: Ir a pestaña
A23: 1 | B23: Incrementar el Parque de Smart User en 500 equipos en el 2026 | C23: ='1. Smart User 500'!$B$4 -> Por asignar | D23: Pre-Sales, Del - DEX | E23: ='1. Smart User 500'!$B$5 -> 500 | F23: =IFERROR(LOOKUP(2,1/('1. Smart User 500'!$D$11:$D$39<>""),'1. Smart User 500'!$D$11:$D$39),"Sin datos") -> 11.01 | G23: =IFERROR(LOOKUP(2,1/('1. Smart User 500'!$D$11:$D$39<>""),'1. Smart User 500'!$H$11:$H$39),"Sin datos") -> En meta | H23: 1. Smart User 500
A24: 2 | B24: Lograr un Monthly Value de $X en advisory en el primer trimestre de 2027 | C24: ='2. MV Advisory'!$B$4 -> Por asignar | D24: Ventas, Customer Success, Pre-Sales, Del - TSS | E24: ='2. MV Advisory'!$B$5 -> 10000 | F24: =IFERROR(LOOKUP(2,1/('2. MV Advisory'!$D$11:$D$52<>""),'2. MV Advisory'!$D$11:$D$52),"Sin datos") -> Sin datos | G24: =IFERROR(LOOKUP(2,1/('2. MV Advisory'!$D$11:$D$52<>""),'2. MV Advisory'!$H$11:$H$52),"Sin datos") -> Sin datos | H24: 2. MV Advisory
A25: 3 | B25: Reconocer 10 negocios mayores a $30K de GP en el 2027 | C25: ='3. Negocios +30K GP'!$B$4 -> Por asignar | D25: Ventas, Pre-Sales | E25: ='3. Negocios +30K GP'!$B$5 -> 10 | F25: =IFERROR(LOOKUP(2,1/('3. Negocios +30K GP'!$D$11:$D$91<>""),'3. Negocios +30K GP'!$D$11:$D$91),"Sin datos") -> 0 | G25: =IFERROR(LOOKUP(2,1/('3. Negocios +30K GP'!$D$11:$D$91<>""),'3. Negocios +30K GP'!$H$11:$H$91),"Sin datos") -> En meta | H25: 3. Negocios +30K GP
A26: 4 | B26: Cumplir el 100% de entregas y colocaciones en tiempo y forma | C26: ='4. Entregas 100%'!$B$4 -> Por asignar | D26: Finanzas | E26: ='4. Entregas 100%'!$B$5 -> 1 | F26: =IFERROR(LOOKUP(2,1/('4. Entregas 100%'!$D$11:$D$91<>""),'4. Entregas 100%'!$D$11:$D$91),"Sin datos") -> Sin datos | G26: =IFERROR(LOOKUP(2,1/('4. Entregas 100%'!$D$11:$D$91<>""),'4. Entregas 100%'!$H$11:$H$91),"Sin datos") -> Sin datos | H26: 4. Entregas 100%
A27: 5 | B27: Incrementar el MV de servicios basados en el DC GBM San Marcos en $20,000 | C27: ='5. MV Datacenter'!$B$4 -> Por asignar | D27: Pre-Sales, Del - DC | E27: ='5. MV Datacenter'!$B$5 -> 20000 | F27: =IFERROR(LOOKUP(2,1/('5. MV Datacenter'!$D$11:$D$91<>""),'5. MV Datacenter'!$D$11:$D$91),"Sin datos") -> Sin datos | G27: =IFERROR(LOOKUP(2,1/('5. MV Datacenter'!$D$11:$D$91<>""),'5. MV Datacenter'!$H$11:$H$91),"Sin datos") -> Sin datos | H27: 5. MV Datacenter
A28: 6 | B28: Tener cero contratos expired en al menos 16 de los próximos 18 meses | C28: ='6. Cero Expired'!$B$4 -> Por asignar | D28: Customer Success, Del - DEX, Del - TSS, Del - DC | E28: ='6. Cero Expired'!$B$5 -> 0 | F28: =IFERROR(LOOKUP(2,1/('6. Cero Expired'!$D$11:$D$91<>""),'6. Cero Expired'!$D$11:$D$91),"Sin datos") -> Sin datos | G28: =IFERROR(LOOKUP(2,1/('6. Cero Expired'!$D$11:$D$91<>""),'6. Cero Expired'!$H$11:$H$91),"Sin datos") -> Sin datos | H28: 6. Cero Expired
A29: 7 | B29: Incrementar el MV de Digital Solutions en $30K/mes al 1ro de mayo 2027 | C29: ='7. MV Digital Sol'!$B$4 -> Por asignar | D29: Ventas, Del - DS | E29: ='7. MV Digital Sol'!$B$5 -> 30000 | F29: =IFERROR(LOOKUP(2,1/('7. MV Digital Sol'!$D$11:$D$56<>""),'7. MV Digital Sol'!$D$11:$D$56),"Sin datos") -> Sin datos | G29: =IFERROR(LOOKUP(2,1/('7. MV Digital Sol'!$D$11:$D$56<>""),'7. MV Digital Sol'!$H$11:$H$56),"Sin datos") -> Sin datos | H29: 7. MV Digital Sol
A30: 8 | B30: Lograr un GP consolidado de 16% en el 2027 | C30: ='8. GP 16%'!$B$4 -> Por asignar | D30: Finanzas (todas las áreas aportan) | E30: ='8. GP 16%'!$B$5 -> 0.16 | F30: =IFERROR(LOOKUP(2,1/('8. GP 16%'!$D$11:$D$28<>""),'8. GP 16%'!$D$11:$D$28),"Sin datos") -> Sin datos | G30: =IFERROR(LOOKUP(2,1/('8. GP 16%'!$D$11:$D$28<>""),'8. GP 16%'!$H$11:$H$28),"Sin datos") -> Sin datos | H30: 8. GP 16%
A31: 9 | B31: Incrementar el CSAT de X a Y, sosteniéndolo 4 meses consecutivos | C31: ='9. CSAT'!$B$4 -> Por asignar | D31: Customer Success (todas las áreas de entrega aportan) | E31: ='9. CSAT'!$B$5 -> 4.5 | F31: =IFERROR(LOOKUP(2,1/('9. CSAT'!$D$11:$D$28<>""),'9. CSAT'!$D$11:$D$28),"Sin datos") -> Sin datos | G31: =IFERROR(LOOKUP(2,1/('9. CSAT'!$D$11:$D$28<>""),'9. CSAT'!$H$11:$H$28),"Sin datos") -> Sin datos | H31: 9. CSAT

Sheet 1. Smart User 500
A1: WIG 1 — Incrementar el Parque de Smart User en 500 equipos en el 2026
A2: Indicador lag: | B2: Equipos Smart User colocados (acumulado). 500 equipos a $40/mes = $6.4K MRR adicional en GP.
A3: De X a Y: | B3: De 0 a 500 equipos colocados, antes del 31 de diciembre de 2026.
A4: Dueño: | B4: Por asignar | D4: Equipo: | E4: Pre-Sales, Del - DEX
A5: Meta: | B5: 500 | D5: Inicio: | E5: 46188 | G5: Fin: | H5: 46384
A6: Leads: | B6: Hasta 8 indicadores predictivos a la derecha. L1–L2 = apuesta principal del equipo; L3–L8 = indicadores de apoyo. Nombre (fila 8) y meta semanal (fila 9) editables en azul.
A8: Periodos: | B8: =COUNT(A11:A39) -> 29 | H8: Lead → | I8: L1. Compromisos de asignación firmados (equipos) | K8: L2. Demos / POCs activos (Promerica, Disnorte, otros) | M8: L3. Presentaciones de oferta Smart User realizadas | O8: L4. Equipos cotizados en la semana | Q8: L5. Equipos en bodega listos para colocar | S8: L6. Clientes nuevos contactados con la oferta | U8: L7. % equipos colocados en ≤2 semanas tras firma | W8: (Disponible)
A9: Celdas azules = se digitan cada lunes. Celdas negras = fórmulas, no tocar. | H9: Meta → | I9: 20 | K9: 2 | M9: 3 | O9: 30 | Q9: 40 | S9: 2 | U9: 1
A10: # | B10: Semana | C10: Meta semana | D10: Real | E10: Meta acum. | F10: Real acum. | G10: % avance | H10: Estado | I10: Real | J10: % | K10: Real | L10: % | M10: Real | N10: % | O10: Real | P10: % | Q10: Real | R10: % | S10: Real | T10: % | U10: Real | V10: % | W10: Real | X10: %
A11: 1 | B11: 46188 | C11: =$B$5/$B$8 -> 17.241379 | D11: =+SUM(I11,K11,M11,O11,Q11,S11,U11,W11) -> 22 | E11: =SUM($C$11:C11) -> 17.241379 | F11: =SUM($D$11:D11) -> 22 | G11: =IF(COUNT($D$11:D11)=0,"",F11/E11) -> 1.276 | H11: =IF(G11="","",IF(G11>=0.95,"En meta",IF(G11>=0.8,"Riesgo","Atrasado"))) -> En meta | I11: 3 | J11: =IF(I11="","",IF($I$9="","",IF($I$9=0,"",I11/$I$9))) -> 0.15 | K11: 2 | L11: =IF(K11="","",IF($K$9="","",IF($K$9=0,"",K11/$K$9))) -> 1 | M11: 5 | N11: =IF(M11="","",IF($M$9="","",IF($M$9=0,"",M11/$M$9))) -> 1.6666667 | O11: 6 | P11: =IF(O11="","",IF($O$9="","",IF($O$9=0,"",O11/$O$9))) -> 0.2 | Q11: 2 | R11: =IF(Q11="","",IF($Q$9="","",IF($Q$9=0,"",Q11/$Q$9))) -> 0.05 | S11: 4 | T11: =IF(S11="","",IF($S$9="","",IF($S$9=0,"",S11/$S$9))) -> 2 | V11: =IF(U11="","",IF($U$9="","",IF($U$9=0,"",U11/$U$9))) | X11: =IF(W11="","",IF($W$9="","",IF($W$9=0,"",W11/$W$9)))
A12: 2 | B12: 46195 | C12: =$B$5/$B$8 -> 17.241379 | D12: =+SUM(I12,K12,M12,O12,Q12,S12,U12,W12) -> 11.01 | E12: =SUM($C$11:C12) -> 34.482759 | F12: =SUM($D$11:D12) -> 33.01 | G12: =IF(COUNT($D$11:D12)=0,"",F12/E12) -> 0.95729 | H12: =IF(G12="","",IF(G12>=0.95,"En meta",IF(G12>=0.8,"Riesgo","Atrasado"))) -> En meta | I12: 1 | J12: =IF(I12="","",IF($I$9="","",IF($I$9=0,"",I12/$I$9))) -> 0.05 | K12: 1 | L12: =IF(K12="","",IF($K$9="","",IF($K$9=0,"",K12/$K$9))) -> 0.5 | M12: 1 | N12: =IF(M12="","",IF($M$9="","",IF($M$9=0,"",M12/$M$9))) -> 0.33333333 | O12: 2 | P12: =IF(O12="","",IF($O$9="","",IF($O$9=0,"",O12/$O$9))) -> 0.066666667 | Q12: 4 | R12: =IF(Q12="","",IF($Q$9="","",IF($Q$9=0,"",Q12/$Q$9))) -> 0.1 | S12: 1 | T12: =IF(S12="","",IF($S$9="","",IF($S$9=0,"",S12/$S$9))) -> 0.5 | U12: 0.01 | V12: =IF(U12="","",IF($U$9="","",IF($U$9=0,"",U12/$U$9))) -> 0.01 | W12: 1 | X12: =IF(W12="","",IF($W$9="","",IF($W$9=0,"",W12/$W$9)))
A13: 3 | B13: 46202 | C13: =$B$5/$B$8 -> 17.241379 | E13: =SUM($C$11:C13) -> 51.724138 | F13: =SUM($D$11:D13) -> 33.01 | G13: =IF(COUNT($D$11:D13)=0,"",F13/E13) -> 0.63819333 | H13: =IF(G13="","",IF(G13>=0.95,"En meta",IF(G13>=0.8,"Riesgo","Atrasado"))) -> Atrasado | J13: =IF(I13="","",IF($I$9="","",IF($I$9=0,"",I13/$I$9))) | L13: =IF(K13="","",IF($K$9="","",IF($K$9=0,"",K13/$K$9))) | N13: =IF(M13="","",IF($M$9="","",IF($M$9=0,"",M13/$M$9))) | P13: =IF(O13="","",IF($O$9="","",IF($O$9=0,"",O13/$O$9))) | R13: =IF(Q13="","",IF($Q$9="","",IF($Q$9=0,"",Q13/$Q$9))) | T13: =IF(S13="","",IF($S$9="","",IF($S$9=0,"",S13/$S$9))) | V13: =IF(U13="","",IF($U$9="","",IF($U$9=0,"",U13/$U$9))) | X13: =IF(W13="","",IF($W$9="","",IF($W$9=0,"",W13/$W$9)))
A14: 4 | B14: 46209 | C14: =$B$5/$B$8 -> 17.241379 | E14: =SUM($C$11:C14) -> 68.965517 | F14: =SUM($D$11:D14) -> 33.01 | G14: =IF(COUNT($D$11:D14)=0,"",F14/E14) -> 0.478645 | H14: =IF(G14="","",IF(G14>=0.95,"En meta",IF(G14>=0.8,"Riesgo","Atrasado"))) -> Atrasado | J14: =IF(I14="","",IF($I$9="","",IF($I$9=0,"",I14/$I$9))) | L14: =IF(K14="","",IF($K$9="","",IF($K$9=0,"",K14/$K$9))) | N14: =IF(M14="","",IF($M$9="","",IF($M$9=0,"",M14/$M$9))) | P14: =IF(O14="","",IF($O$9="","",IF($O$9=0,"",O14/$O$9))) | R14: =IF(Q14="","",IF($Q$9="","",IF($Q$9=0,"",Q14/$Q$9))) | T14: =IF(S14="","",IF($S$9="","",IF($S$9=0,"",S14/$S$9))) | V14: =IF(U14="","",IF($U$9="","",IF($U$9=0,"",U14/$U$9))) | X14: =IF(W14="","",IF($W$9="","",IF($W$9=0,"",W14/$W$9)))
A15: 5 | B15: 46216 | C15: =$B$5/$B$8 -> 17.241379 | E15: =SUM($C$11:C15) -> 86.206897 | F15: =SUM($D$11:D15) -> 33.01 | G15: =IF(COUNT($D$11:D15)=0,"",F15/E15) -> 0.382916 | H15: =IF(G15="","",IF(G15>=0.95,"En meta",IF(G15>=0.8,"Riesgo","Atrasado"))) -> Atrasado | J15: =IF(I15="","",IF($I$9="","",IF($I$9=0,"",I15/$I$9))) | L15: =IF(K15="","",IF($K$9="","",IF($K$9=0,"",K15/$K$9))) | N15: =IF(M15="","",IF($M$9="","",IF($M$9=0,"",M15/$M$9))) | P15: =IF(O15="","",IF($O$9="","",IF($O$9=0,"",O15/$O$9))) | R15: =IF(Q15="","",IF($Q$9="","",IF($Q$9=0,"",Q15/$Q$9))) | T15: =IF(S15="","",IF($S$9="","",IF($S$9=0,"",S15/$S$9))) | V15: =IF(U15="","",IF($U$9="","",IF($U$9=0,"",U15/$U$9))) | X15: =IF(W15="","",IF($W$9="","",IF($W$9=0,"",W15/$W$9)))
A16: 6 | B16: 46223 | C16: =$B$5/$B$8 -> 17.241379 | E16: =SUM($C$11:C16) -> 103.44828 | F16: =SUM($D$11:D16) -> 33.01 | G16: =IF(COUNT($D$11:D16)=0,"",F16/E16) -> 0.31909667 | H16: =IF(G16="","",IF(G16>=0.95,"En meta",IF(G16>=0.8,"Riesgo","Atrasado"))) -> Atrasado | J16: =IF(I16="","",IF($I$9="","",IF($I$9=0,"",I16/$I$9))) | L16: =IF(K16="","",IF($K$9="","",IF($K$9=0,"",K16/$K$9))) | N16: =IF(M16="","",IF($M$9="","",IF($M$9=0,"",M16/$M$9))) | P16: =IF(O16="","",IF($O$9="","",IF($O$9=0,"",O16/$O$9))) | R16: =IF(Q16="","",IF($Q$9="","",IF($Q$9=0,"",Q16/$Q$9))) | T16: =IF(S16="","",IF($S$9="","",IF($S$9=0,"",S16/$S$9))) | V16: =IF(U16="","",IF($U$9="","",IF($U$9=0,"",U16/$U$9))) | X16: =IF(W16="","",IF($W$9="","",IF($W$9=0,"",W16/$W$9)))
A17: 7 | B17: 46230 | C17: =$B$5/$B$8 -> 17.241379 | E17: =SUM($C$11:C17) -> 120.68966 | F17: =SUM($D$11:D17) -> 33.01 | G17: =IF(COUNT($D$11:D17)=0,"",F17/E17) -> 0.27351143 | H17: =IF(G17="","",IF(G17>=0.95,"En meta",IF(G17>=0.8,"Riesgo","Atrasado"))) -> Atrasado | J17: =IF(I17="","",IF($I$9="","",IF($I$9=0,"",I17/$I$9))) | L17: =IF(K17="","",IF($K$9="","",IF($K$9=0,"",K17/$K$9))) | N17: =IF(M17="","",IF($M$9="","",IF($M$9=0,"",M17/$M$9))) | P17: =IF(O17="","",IF($O$9="","",IF($O$9=0,"",O17/$O$9))) | R17: =IF(Q17="","",IF($Q$9="","",IF($Q$9=0,"",Q17/$Q$9))) | T17: =IF(S17="","",IF($S$9="","",IF($S$9=0,"",S17/$S$9))) | V17: =IF(U17="","",IF($U$9="","",IF($U$9=0,"",U17/$U$9))) | X17: =IF(W17="","",IF($W$9="","",IF($W$9=0,"",W17/$W$9)))
A18: 8 | B18: 46237 | C18: =$B$5/$B$8 -> 17.241379 | E18: =SUM($C$11:C18) -> 137.93103 | F18: =SUM($D$11:D18) -> 33.01 | G18: =IF(COUNT($D$11:D18)=0,"",F18/E18) -> 0.2393225 | H18: =IF(G18="","",IF(G18>=0.95,"En meta",IF(G18>=0.8,"Riesgo","Atrasado"))) -> Atrasado | J18: =IF(I18="","",IF($I$9="","",IF($I$9=0,"",I18/$I$9))) | L18: =IF(K18="","",IF($K$9="","",IF($K$9=0,"",K18/$K$9))) | N18: =IF(M18="","",IF($M$9="","",IF($M$9=0,"",M18/$M$9))) | P18: =IF(O18="","",IF($O$9="","",IF($O$9=0,"",O18/$O$9))) | R18: =IF(Q18="","",IF($Q$9="","",IF($Q$9=0,"",Q18/$Q$9))) | T18: =IF(S18="","",IF($S$9="","",IF($S$9=0,"",S18/$S$9))) | V18: =IF(U18="","",IF($U$9="","",IF($U$9=0,"",U18/$U$9))) | X18: =IF(W18="","",IF($W$9="","",IF($W$9=0,"",W18/$W$9)))
A19: 9 | B19: 46244 | C19: =$B$5/$B$8 -> 17.241379 | E19: =SUM($C$11:C19) -> 155.17241 | F19: =SUM($D$11:D19) -> 33.01 | G19: =IF(COUNT($D$11:D19)=0,"",F19/E19) -> 0.21273111 | H19: =IF(G19="","",IF(G19>=0.95,"En meta",IF(G19>=0.8,"Riesgo","Atrasado"))) -> Atrasado | J19: =IF(I19="","",IF($I$9="","",IF($I$9=0,"",I19/$I$9))) | L19: =IF(K19="","",IF($K$9="","",IF($K$9=0,"",K19/$K$9))) | N19: =IF(M19="","",IF($M$9="","",IF($M$9=0,"",M19/$M$9))) | P19: =IF(O19="","",IF($O$9="","",IF($O$9=0,"",O19/$O$9))) | R19: =IF(Q19="","",IF($Q$9="","",IF($Q$9=0,"",Q19/$Q$9))) | T19: =IF(S19="","",IF($S$9="","",IF($S$9=0,"",S19/$S$9))) | V19: =IF(U19="","",IF($U$9="","",IF($U$9=0,"",U19/$U$9))) | X19: =IF(W19="","",IF($W$9="","",IF($W$9=0,"",W19/$W$9)))
A20: 10 | B20: 46251 | C20: =$B$5/$B$8 -> 17.241379 | E20: =SUM($C$11:C20) -> 172.41379 | F20: =SUM($D$11:D20) -> 33.01 | G20: =IF(COUNT($D$11:D20)=0,"",F20/E20) -> 0.191458 | H20: =IF(G20="","",IF(G20>=0.95,"En meta",IF(G20>=0.8,"Riesgo","Atrasado"))) -> Atrasado | J20: =IF(I20="","",IF($I$9="","",IF($I$9=0,"",I20/$I$9))) | L20: =IF(K20="","",IF($K$9="","",IF($K$9=0,"",K20/$K$9))) | N20: =IF(M20="","",IF($M$9="","",IF($M$9=0,"",M20/$M$9))) | P20: =IF(O20="","",IF($O$9="","",IF($O$9=0,"",O20/$O$9))) | R20: =IF(Q20="","",IF($Q$9="","",IF($Q$9=0,"",Q20/$Q$9))) | T20: =IF(S20="","",IF($S$9="","",IF($S$9=0,"",S20/$S$9))) | V20: =IF(U20="","",IF($U$9="","",IF($U$9=0,"",U20/$U$9))) | X20: =IF(W20="","",IF($W$9="","",IF($W$9=0,"",W20/$W$9)))
A21: 11 | B21: 46258 | C21: =$B$5/$B$8 -> 17.241379 | E21: =SUM($C$11:C21) -> 189.65517 | F21: =SUM($D$11:D21) -> 33.01 | G21: =IF(COUNT($D$11:D21)=0,"",F21/E21) -> 0.17405273 | H21: =IF(G21="","",IF(G21>=0.95,"En meta",IF(G21>=0.8,"Riesgo","Atrasado"))) -> Atrasado | J21: =IF(I21="","",IF($I$9="","",IF($I$9=0,"",I21/$I$9))) | L21: =IF(K21="","",IF($K$9="","",IF($K$9=0,"",K21/$K$9))) | N21: =IF(M21="","",IF($M$9="","",IF($M$9=0,"",M21/$M$9))) | P21: =IF(O21="","",IF($O$9="","",IF($O$9=0,"",O21/$O$9))) | R21: =IF(Q21="","",IF($Q$9="","",IF($Q$9=0,"",Q21/$Q$9))) | T21: =IF(S21="","",IF($S$9="","",IF($S$9=0,"",S21/$S$9))) | V21: =IF(U21="","",IF($U$9="","",IF($U$9=0,"",U21/$U$9))) | X21: =IF(W21="","",IF($W$9="","",IF($W$9=0,"",W21/$W$9)))
A22: 12 | B22: 46265 | C22: =$B$5/$B$8 -> 17.241379 | E22: =SUM($C$11:C22) -> 206.89655 | F22: =SUM($D$11:D22) -> 33.01 | G22: =IF(COUNT($D$11:D22)=0,"",F22/E22) -> 0.15954833 | H22: =IF(G22="","",IF(G22>=0.95,"En meta",IF(G22>=0.8,"Riesgo","Atrasado"))) -> Atrasado | J22: =IF(I22="","",IF($I$9="","",IF($I$9=0,"",I22/$I$9))) | L22: =IF(K22="","",IF($K$9="","",IF($K$9=0,"",K22/$K$9))) | N22: =IF(M22="","",IF($M$9="","",IF($M$9=0,"",M22/$M$9))) | P22: =IF(O22="","",IF($O$9="","",IF($O$9=0,"",O22/$O$9))) | R22: =IF(Q22="","",IF($Q$9="","",IF($Q$9=0,"",Q22/$Q$9))) | T22: =IF(S22="","",IF($S$9="","",IF($S$9=0,"",S22/$S$9))) | V22: =IF(U22="","",IF($U$9="","",IF($U$9=0,"",U22/$U$9))) | X22: =IF(W22="","",IF($W$9="","",IF($W$9=0,"",W22/$W$9)))
A23: 13 | B23: 46272 | C23: =$B$5/$B$8 -> 17.241379 | E23: =SUM($C$11:C23) -> 224.13793 | F23: =SUM($D$11:D23) -> 33.01 | G23: =IF(COUNT($D$11:D23)=0,"",F23/E23) -> 0.14727538 | H23: =IF(G23="","",IF(G23>=0.95,"En meta",IF(G23>=0.8,"Riesgo","Atrasado"))) -> Atrasado | J23: =IF(I23="","",IF($I$9="","",IF($I$9=0,"",I23/$I$9))) | L23: =IF(K23="","",IF($K$9="","",IF($K$9=0,"",K23/$K$9))) | N23: =IF(M23="","",IF($M$9="","",IF($M$9=0,"",M23/$M$9))) | P23: =IF(O23="","",IF($O$9="","",IF($O$9=0,"",O23/$O$9))) | R23: =IF(Q23="","",IF($Q$9="","",IF($Q$9=0,"",Q23/$Q$9))) | T23: =IF(S23="","",IF($S$9="","",IF($S$9=0,"",S23/$S$9))) | V23: =IF(U23="","",IF($U$9="","",IF($U$9=0,"",U23/$U$9))) | X23: =IF(W23="","",IF($W$9="","",IF($W$9=0,"",W23/$W$9)))
A24: 14 | B24: 46279 | C24: =$B$5/$B$8 -> 17.241379 | E24: =SUM($C$11:C24) -> 241.37931 | F24: =SUM($D$11:D24) -> 33.01 | G24: =IF(COUNT($D$11:D24)=0,"",F24/E24) -> 0.13675571 | H24: =IF(G24="","",IF(G24>=0.95,"En meta",IF(G24>=0.8,"Riesgo","Atrasado"))) -> Atrasado | J24: =IF(I24="","",IF($I$9="","",IF($I$9=0,"",I24/$I$9))) | L24: =IF(K24="","",IF($K$9="","",IF($K$9=0,"",K24/$K$9))) | N24: =IF(M24="","",IF($M$9="","",IF($M$9=0,"",M24/$M$9))) | P24: =IF(O24="","",IF($O$9="","",IF($O$9=0,"",O24/$O$9))) | R24: =IF(Q24="","",IF($Q$9="","",IF($Q$9=0,"",Q24/$Q$9))) | T24: =IF(S24="","",IF($S$9="","",IF($S$9=0,"",S24/$S$9))) | V24: =IF(U24="","",IF($U$9="","",IF($U$9=0,"",U24/$U$9))) | X24: =IF(W24="","",IF($W$9="","",IF($W$9=0,"",W24/$W$9)))
... A39: 29 | B39: 46384 | C39: =$B$5/$B$8 -> 17.241379 | E39: =SUM($C$11:C39) -> 500 | F39: =SUM($D$11:D39) -> 33.01 | G39: =IF(COUNT($D$11:D39)=0,"",F39/E39) -> 0.06602 | H39: =IF(G39="","",IF(G39>=0.95,"En meta",IF(G39>=0.8,"Riesgo","Atrasado"))) -> Atrasado | J39: =IF(I39="","",IF($I$9="","",IF($I$9=0,"",I39/$I$9))) | L39: =IF(K39="","",IF($K$9="","",IF($K$9=0,"",K39/$K$9))) | N39: =IF(M39="","",IF($M$9="","",IF($M$9=0,"",M39/$M$9))) | P39: =IF(O39="","",IF($O$9="","",IF($O$9=0,"",O39/$O$9))) | R39: =IF(Q39="","",IF($Q$9="","",IF($Q$9=0,"",Q39/$Q$9))) | T39: =IF(S39="","",IF($S$9="","",IF($S$9=0,"",S39/$S$9))) | V39: =IF(U39="","",IF($U$9="","",IF($U$9=0,"",U39/$U$9))) | X39: =IF(W39="","",IF($W$9="","",IF($W$9=0,"",W39/$W$9)))

Sheet 2. MV Advisory
A1: WIG 2 — Lograr un Monthly Value de $X en advisory en el primer trimestre de 2027
A2: Indicador lag: | B2: MV de horas advisory de ingenieros locales vendidas (USD acumulado). Costo fijo ya cubierto = mayor utilidad.
A3: De X a Y: | B3: De $0 a la meta de MV advisory, antes del 31 de marzo de 2027. (Definir $X en la celda Meta)
A4: Dueño: | B4: Por asignar | D4: Equipo: | E4: Ventas, Customer Success, Pre-Sales, Del - TSS
A5: Meta: | B5: 10000 | D5: Inicio: | E5: 46188 | G5: Fin: | H5: 46475
A6: Leads: | B6: Hasta 8 indicadores predictivos a la derecha. L1–L2 = apuesta principal del equipo; L3–L8 = indicadores de apoyo. Nombre (fila 8) y meta semanal (fila 9) editables en azul.
A8: Periodos: | B8: =COUNT(A11:A52) -> 42 | H8: Lead → | I8: L1. Propuestas de advisory presentadas | K8: L2. Horas advisory cotizadas | M8: L3. Reuniones de venta consultiva con clientes | O8: L4. Assessments / health checks ofrecidos | Q8: L5. % utilización de ingenieros locales en advisory | S8: L6. Opps de advisory activas en pipeline | U8: L7. Contratos advisory firmados en la semana | W8: (Disponible)
A9: Celdas azules = se digitan cada lunes. Celdas negras = fórmulas, no tocar. | H9: Meta → | I9: 3 | K9: 40 | M9: 4 | O9: 2 | Q9: 0.2 | S9: 6 | U9: 1
A10: # | B10: Semana | C10: Meta semana | D10: Real | E10: Meta acum. | F10: Real acum. | G10: % avance | H10: Estado | I10: Real | J10: % | K10: Real | L10: % | M10: Real | N10: % | O10: Real | P10: % | Q10: Real | R10: % | S10: Real | T10: % | U10: Real | V10: % | W10: Real | X10: %
A11: 1 | B11: 46188 | C11: =$B$5/$B$8 -> 238.09524 | E11: =SUM($C$11:C11) -> 238.09524 | F11: =SUM($D$11:D11) -> 0 | G11: =IF(COUNT($D$11:D11)=0,"",F11/E11) | H11: =IF(G11="","",IF(G11>=0.95,"En meta",IF(G11>=0.8,"Riesgo","Atrasado"))) | J11: =IF(I11="","",IF($I$9="","",IF($I$9=0,"",I11/$I$9))) | L11: =IF(K11="","",IF($K$9="","",IF($K$9=0,"",K11/$K$9))) | N11: =IF(M11="","",IF($M$9="","",IF($M$9=0,"",M11/$M$9))) | P11: =IF(O11="","",IF($O$9="","",IF($O$9=0,"",O11/$O$9))) | R11: =IF(Q11="","",IF($Q$9="","",IF($Q$9=0,"",Q11/$Q$9))) | T11: =IF(S11="","",IF($S$9="","",IF($S$9=0,"",S11/$S$9))) | V11: =IF(U11="","",IF($U$9="","",IF($U$9=0,"",U11/$U$9))) | X11: =IF(W11="","",IF($W$9="","",IF($W$9=0,"",W11/$W$9)))
A12: 2 | B12: 46195 | C12: =$B$5/$B$8 -> 238.09524 | E12: =SUM($C$11:C12) -> 476.19048 | F12: =SUM($D$11:D12) -> 0 | G12: =IF(COUNT($D$11:D12)=0,"",F12/E12) | H12: =IF(G12="","",IF(G12>=0.95,"En meta",IF(G12>=0.8,"Riesgo","Atrasado"))) | J12: =IF(I12="","",IF($I$9="","",IF($I$9=0,"",I12/$I$9))) | L12: =IF(K12="","",IF($K$9="","",IF($K$9=0,"",K12/$K$9))) | N12: =IF(M12="","",IF($M$9="","",IF($M$9=0,"",M12/$M$9))) | P12: =IF(O12="","",IF($O$9="","",IF($O$9=0,"",O12/$O$9))) | R12: =IF(Q12="","",IF($Q$9="","",IF($Q$9=0,"",Q12/$Q$9))) | T12: =IF(S12="","",IF($S$9="","",IF($S$9=0,"",S12/$S$9))) | V12: =IF(U12="","",IF($U$9="","",IF($U$9=0,"",U12/$U$9))) | X12: =IF(W12="","",IF($W$9="","",IF($W$9=0,"",W12/$W$9)))
A13: 3 | B13: 46202 | C13: =$B$5/$B$8 -> 238.09524 | E13: =SUM($C$11:C13) -> 714.28571 | F13: =SUM($D$11:D13) -> 0 | G13: =IF(COUNT($D$11:D13)=0,"",F13/E13) | H13: =IF(G13="","",IF(G13>=0.95,"En meta",IF(G13>=0.8,"Riesgo","Atrasado"))) | J13: =IF(I13="","",IF($I$9="","",IF($I$9=0,"",I13/$I$9))) | L13: =IF(K13="","",IF($K$9="","",IF($K$9=0,"",K13/$K$9))) | N13: =IF(M13="","",IF($M$9="","",IF($M$9=0,"",M13/$M$9))) | P13: =IF(O13="","",IF($O$9="","",IF($O$9=0,"",O13/$O$9))) | R13: =IF(Q13="","",IF($Q$9="","",IF($Q$9=0,"",Q13/$Q$9))) | T13: =IF(S13="","",IF($S$9="","",IF($S$9=0,"",S13/$S$9))) | V13: =IF(U13="","",IF($U$9="","",IF($U$9=0,"",U13/$U$9))) | X13: =IF(W13="","",IF($W$9="","",IF($W$9=0,"",W13/$W$9)))
A14: 4 | B14: 46209 | C14: =$B$5/$B$8 -> 238.09524 | E14: =SUM($C$11:C14) -> 952.38095 | F14: =SUM($D$11:D14) -> 0 | G14: =IF(COUNT($D$11:D14)=0,"",F14/E14) | H14: =IF(G14="","",IF(G14>=0.95,"En meta",IF(G14>=0.8,"Riesgo","Atrasado"))) | J14: =IF(I14="","",IF($I$9="","",IF($I$9=0,"",I14/$I$9))) | L14: =IF(K14="","",IF($K$9="","",IF($K$9=0,"",K14/$K$9))) | N14: =IF(M14="","",IF($M$9="","",IF($M$9=0,"",M14/$M$9))) | P14: =IF(O14="","",IF($O$9="","",IF($O$9=0,"",O14/$O$9))) | R14: =IF(Q14="","",IF($Q$9="","",IF($Q$9=0,"",Q14/$Q$9))) | T14: =IF(S14="","",IF($S$9="","",IF($S$9=0,"",S14/$S$9))) | V14: =IF(U14="","",IF($U$9="","",IF($U$9=0,"",U14/$U$9))) | X14: =IF(W14="","",IF($W$9="","",IF($W$9=0,"",W14/$W$9)))
A15: 5 | B15: 46216 | C15: =$B$5/$B$8 -> 238.09524 | E15: =SUM($C$11:C15) -> 1190.4762 | F15: =SUM($D$11:D15) -> 0 | G15: =IF(COUNT($D$11:D15)=0,"",F15/E15) | H15: =IF(G15="","",IF(G15>=0.95,"En meta",IF(G15>=0.8,"Riesgo","Atrasado"))) | J15: =IF(I15="","",IF($I$9="","",IF($I$9=0,"",I15/$I$9))) | L15: =IF(K15="","",IF($K$9="","",IF($K$9=0,"",K15/$K$9))) | N15: =IF(M15="","",IF($M$9="","",IF($M$9=0,"",M15/$M$9))) | P15: =IF(O15="","",IF($O$9="","",IF($O$9=0,"",O15/$O$9))) | R15: =IF(Q15="","",IF($Q$9="","",IF($Q$9=0,"",Q15/$Q$9))) | T15: =IF(S15="","",IF($S$9="","",IF($S$9=0,"",S15/$S$9))) | V15: =IF(U15="","",IF($U$9="","",IF($U$9=0,"",U15/$U$9))) | X15: =IF(W15="","",IF($W$9="","",IF($W$9=0,"",W15/$W$9)))
A16: 6 | B16: 46223 | C16: =$B$5/$B$8 -> 238.09524 | E16: =SUM($C$11:C16) -> 1428.5714 | F16: =SUM($D$11:D16) -> 0 | G16: =IF(COUNT($D$11:D16)=0,"",F16/E16) | H16: =IF(G16="","",IF(G16>=0.95,"En meta",IF(G16>=0.8,"Riesgo","Atrasado"))) | J16: =IF(I16="","",IF($I$9="","",IF($I$9=0,"",I16/$I$9))) | L16: =IF(K16="","",IF($K$9="","",IF($K$9=0,"",K16/$K$9))) | N16: =IF(M16="","",IF($M$9="","",IF($M$9=0,"",M16/$M$9))) | P16: =IF(O16="","",IF($O$9="","",IF($O$9=0,"",O16/$O$9))) | R16: =IF(Q16="","",IF($Q$9="","",IF($Q$9=0,"",Q16/$Q$9))) | T16: =IF(S16="","",IF($S$9="","",IF($S$9=0,"",S16/$S$9))) | V16: =IF(U16="","",IF($U$9="","",IF($U$9=0,"",U16/$U$9))) | X16: =IF(W16="","",IF($W$9="","",IF($W$9=0,"",W16/$W$9)))
A17: 7 | B17: 46230 | C17: =$B$5/$B$8 -> 238.09524 | E17: =SUM($C$11:C17) -> 1666.6667 | F17: =SUM($D$11:D17) -> 0 | G17: =IF(COUNT($D$11:D17)=0,"",F17/E17) | H17: =IF(G17="","",IF(G17>=0.95,"En meta",IF(G17>=0.8,"Riesgo","Atrasado"))) | J17: =IF(I17="","",IF($I$9="","",IF($I$9=0,"",I17/$I$9))) | L17: =IF(K17="","",IF($K$9="","",IF($K$9=0,"",K17/$K$9))) | N17: =IF(M17="","",IF($M$9="","",IF($M$9=0,"",M17/$M$9))) | P17: =IF(O17="","",IF($O$9="","",IF($O$9=0,"",O17/$O$9))) | R17: =IF(Q17="","",IF($Q$9="","",IF($Q$9=0,"",Q17/$Q$9))) | T17: =IF(S17="","",IF($S$9="","",IF($S$9=0,"",S17/$S$9))) | V17: =IF(U17="","",IF($U$9="","",IF($U$9=0,"",U17/$U$9))) | X17: =IF(W17="","",IF($W$9="","",IF($W$9=0,"",W17/$W$9)))
A18: 8 | B18: 46237 | C18: =$B$5/$B$8 -> 238.09524 | E18: =SUM($C$11:C18) -> 1904.7619 | F18: =SUM($D$11:D18) -> 0 | G18: =IF(COUNT($D$11:D18)=0,"",F18/E18) | H18: =IF(G18="","",IF(G18>=0.95,"En meta",IF(G18>=0.8,"Riesgo","Atrasado"))) | J18: =IF(I18="","",IF($I$9="","",IF($I$9=0,"",I18/$I$9))) | L18: =IF(K18="","",IF($K$9="","",IF($K$9=0,"",K18/$K$9))) | N18: =IF(M18="","",IF($M$9="","",IF($M$9=0,"",M18/$M$9))) | P18: =IF(O18="","",IF($O$9="","",IF($O$9=0,"",O18/$O$9))) | R18: =IF(Q18="","",IF($Q$9="","",IF($Q$9=0,"",Q18/$Q$9))) | T18: =IF(S18="","",IF($S$9="","",IF($S$9=0,"",S18/$S$9))) | V18: =IF(U18="","",IF($U$9="","",IF($U$9=0,"",U18/$U$9))) | X18: =IF(W18="","",IF($W$9="","",IF($W$9=0,"",W18/$W$9)))
A19: 9 | B19: 46244 | C19: =$B$5/$B$8 -> 238.09524 | E19: =SUM($C$11:C19) -> 2142.8571 | F19: =SUM($D$11:D19) -> 0 | G19: =IF(COUNT($D$11:D19)=0,"",F19/E19) | H19: =IF(G19="","",IF(G19>=0.95,"En meta",IF(G19>=0.8,"Riesgo","Atrasado"))) | J19: =IF(I19="","",IF($I$9="","",IF($I$9=0,"",I19/$I$9))) | L19: =IF(K19="","",IF($K$9="","",IF($K$9=0,"",K19/$K$9))) | N19: =IF(M19="","",IF($M$9="","",IF($M$9=0,"",M19/$M$9))) | P19: =IF(O19="","",IF($O$9="","",IF($O$9=0,"",O19/$O$9))) | R19: =IF(Q19="","",IF($Q$9="","",IF($Q$9=0,"",Q19/$Q$9))) | T19: =IF(S19="","",IF($S$9="","",IF($S$9=0,"",S19/$S$9))) | V19: =IF(U19="","",IF($U$9="","",IF($U$9=0,"",U19/$U$9))) | X19: =IF(W19="","",IF($W$9="","",IF($W$9=0,"",W19/$W$9)))
A20: 10 | B20: 46251 | C20: =$B$5/$B$8 -> 238.09524 | E20: =SUM($C$11:C20) -> 2380.9524 | F20: =SUM($D$11:D20) -> 0 | G20: =IF(COUNT($D$11:D20)=0,"",F20/E20) | H20: =IF(G20="","",IF(G20>=0.95,"En meta",IF(G20>=0.8,"Riesgo","Atrasado"))) | J20: =IF(I20="","",IF($I$9="","",IF($I$9=0,"",I20/$I$9))) | L20: =IF(K20="","",IF($K$9="","",IF($K$9=0,"",K20/$K$9))) | N20: =IF(M20="","",IF($M$9="","",IF($M$9=0,"",M20/$M$9))) | P20: =IF(O20="","",IF($O$9="","",IF($O$9=0,"",O20/$O$9))) | R20: =IF(Q20="","",IF($Q$9="","",IF($Q$9=0,"",Q20/$Q$9))) | T20: =IF(S20="","",IF($S$9="","",IF($S$9=0,"",S20/$S$9))) | V20: =IF(U20="","",IF($U$9="","",IF($U$9=0,"",U20/$U$9))) | X20: =IF(W20="","",IF($W$9="","",IF($W$9=0,"",W20/$W$9)))
A21: 11 | B21: 46258 | C21: =$B$5/$B$8 -> 238.09524 | E21: =SUM($C$11:C21) -> 2619.0476 | F21: =SUM($D$11:D21) -> 0 | G21: =IF(COUNT($D$11:D21)=0,"",F21/E21) | H21: =IF(G21="","",IF(G21>=0.95,"En meta",IF(G21>=0.8,"Riesgo","Atrasado"))) | J21: =IF(I21="","",IF($I$9="","",IF($I$9=0,"",I21/$I$9))) | L21: =IF(K21="","",IF($K$9="","",IF($K$9=0,"",K21/$K$9))) | N21: =IF(M21="","",IF($M$9="","",IF($M$9=0,"",M21/$M$9))) | P21: =IF(O21="","",IF($O$9="","",IF($O$9=0,"",O21/$O$9))) | R21: =IF(Q21="","",IF($Q$9="","",IF($Q$9=0,"",Q21/$Q$9))) | T21: =IF(S21="","",IF($S$9="","",IF($S$9=0,"",S21/$S$9))) | V21: =IF(U21="","",IF($U$9="","",IF($U$9=0,"",U21/$U$9))) | X21: =IF(W21="","",IF($W$9="","",IF($W$9=0,"",W21/$W$9)))
A22: 12 | B22: 46265 | C22: =$B$5/$B$8 -> 238.09524 | E22: =SUM($C$11:C22) -> 2857.1429 | F22: =SUM($D$11:D22) -> 0 | G22: =IF(COUNT($D$11:D22)=0,"",F22/E22) | H22: =IF(G22="","",IF(G22>=0.95,"En meta",IF(G22>=0.8,"Riesgo","Atrasado"))) | J22: =IF(I22="","",IF($I$9="","",IF($I$9=0,"",I22/$I$9))) | L22: =IF(K22="","",IF($K$9="","",IF($K$9=0,"",K22/$K$9))) | N22: =IF(M22="","",IF($M$9="","",IF($M$9=0,"",M22/$M$9))) | P22: =IF(O22="","",IF($O$9="","",IF($O$9=0,"",O22/$O$9))) | R22: =IF(Q22="","",IF($Q$9="","",IF($Q$9=0,"",Q22/$Q$9))) | T22: =IF(S22="","",IF($S$9="","",IF($S$9=0,"",S22/$S$9))) | V22: =IF(U22="","",IF($U$9="","",IF($U$9=0,"",U22/$U$9))) | X22: =IF(W22="","",IF($W$9="","",IF($W$9=0,"",W22/$W$9)))
... A52: 42 | B52: 46475 | C52: =$B$5/$B$8 -> 238.09524 | E52: =SUM($C$11:C52) -> 10000 | F52: =SUM($D$11:D52) -> 0 | G52: =IF(COUNT($D$11:D52)=0,"",F52/E52) | H52: =IF(G52="","",IF(G52>=0.95,"En meta",IF(G52>=0.8,"Riesgo","Atrasado"))) | J52: =IF(I52="","",IF($I$9="","",IF($I$9=0,"",I52/$I$9))) | L52: =IF(K52="","",IF($K$9="","",IF($K$9=0,"",K52/$K$9))) | N52: =IF(M52="","",IF($M$9="","",IF($M$9=0,"",M52/$M$9))) | P52: =IF(O52="","",IF($O$9="","",IF($O$9=0,"",O52/$O$9))) | R52: =IF(Q52="","",IF($Q$9="","",IF($Q$9=0,"",Q52/$Q$9))) | T52: =IF(S52="","",IF($S$9="","",IF($S$9=0,"",S52/$S$9))) | V52: =IF(U52="","",IF($U$9="","",IF($U$9=0,"",U52/$U$9))) | X52: =IF(W52="","",IF($W$9="","",IF($W$9=0,"",W52/$W$9)))

Sheet 3. Negocios +30K GP
A1: WIG 3 — Reconocer 10 negocios mayores a $30K de GP en el 2027
A2: Indicador lag: | B2: Negocios con GP > $30K reconocidos (acumulado). Negocios grandes que mueven el NAT.
A3: De X a Y: | B3: De 0 a 10 negocios > $30K GP reconocidos, antes del 31 de diciembre de 2027.
A4: Dueño: | B4: Por asignar | D4: Equipo: | E4: Ventas, Pre-Sales
A5: Meta: | B5: 10 | D5: Inicio: | E5: 46188 | G5: Fin: | H5: 46748
A6: Leads: | B6: Hasta 8 indicadores predictivos a la derecha. L1–L2 = apuesta principal del equipo; L3–L8 = indicadores de apoyo. Nombre (fila 8) y meta semanal (fila 9) editables en azul.
A8: Periodos: | B8: =COUNT(A11:A91) -> 81 | H8: Lead → | I8: L1. Opps > $30K GP activas en pipeline | K8: L2. Opps nuevas ingresadas en la semana | M8: L3. Propuestas > $30K presentadas | O8: L4. Reuniones C-level realizadas | Q8: L5. Leads activas al cierre de la semana | S8: L6. Opps > $30K avanzadas de etapa | U8: L7. Win rate de opps > $30K (acumulado) | W8: (Disponible)
A9: Celdas azules = se digitan cada lunes. Celdas negras = fórmulas, no tocar. | H9: Meta → | I9: 5 | K9: 4 | M9: 1 | O9: 2 | Q9: 10 | S9: 2 | U9: 0.3
A10: # | B10: Semana | C10: Meta semana | D10: Real | E10: Meta acum. | F10: Real acum. | G10: % avance | H10: Estado | I10: Real | J10: % | K10: Real | L10: % | M10: Real | N10: % | O10: Real | P10: % | Q10: Real | R10: % | S10: Real | T10: % | U10: Real | V10: % | W10: Real | X10: %
A11: 1 | B11: 46188 | C11: =$B$5/$B$8 -> 0.12345679 | D11: =+SUM(I11,K11,M11,O11,Q11,S11,U11,W11) -> 1 | E11: =SUM($C$11:C11) -> 0.12345679 | F11: =SUM($D$11:D11) -> 1 | G11: =IF(COUNT($D$11:D11)=0,"",F11/E11) -> 8.1 | H11: =IF(G11="","",IF(G11>=0.95,"En meta",IF(G11>=0.8,"Riesgo","Atrasado"))) -> En meta | I11: 1 | J11: =IF(I11="","",IF($I$9="","",IF($I$9=0,"",I11/$I$9))) -> 0.2 | L11: =IF(K11="","",IF($K$9="","",IF($K$9=0,"",K11/$K$9))) | N11: =IF(M11="","",IF($M$9="","",IF($M$9=0,"",M11/$M$9))) | P11: =IF(O11="","",IF($O$9="","",IF($O$9=0,"",O11/$O$9))) | R11: =IF(Q11="","",IF($Q$9="","",IF($Q$9=0,"",Q11/$Q$9))) | T11: =IF(S11="","",IF($S$9="","",IF($S$9=0,"",S11/$S$9))) | V11: =IF(U11="","",IF($U$9="","",IF($U$9=0,"",U11/$U$9))) | X11: =IF(W11="","",IF($W$9="","",IF($W$9=0,"",W11/$W$9)))
A12: 2 | B12: 46195 | C12: =$B$5/$B$8 -> 0.12345679 | D12: =+SUM(I12,K12,M12,O12,Q12,S12,U12,W12) -> 2 | E12: =SUM($C$11:C12) -> 0.24691358 | F12: =SUM($D$11:D12) -> 3 | G12: =IF(COUNT($D$11:D12)=0,"",F12/E12) -> 12.15 | H12: =IF(G12="","",IF(G12>=0.95,"En meta",IF(G12>=0.8,"Riesgo","Atrasado"))) -> En meta | I12: 2 | J12: =IF(I12="","",IF($I$9="","",IF($I$9=0,"",I12/$I$9))) -> 0.4 | L12: =IF(K12="","",IF($K$9="","",IF($K$9=0,"",K12/$K$9))) | N12: =IF(M12="","",IF($M$9="","",IF($M$9=0,"",M12/$M$9))) | P12: =IF(O12="","",IF($O$9="","",IF($O$9=0,"",O12/$O$9))) | R12: =IF(Q12="","",IF($Q$9="","",IF($Q$9=0,"",Q12/$Q$9))) | T12: =IF(S12="","",IF($S$9="","",IF($S$9=0,"",S12/$S$9))) | V12: =IF(U12="","",IF($U$9="","",IF($U$9=0,"",U12/$U$9))) | X12: =IF(W12="","",IF($W$9="","",IF($W$9=0,"",W12/$W$9)))
A13: 3 | B13: 46202 | C13: =$B$5/$B$8 -> 0.12345679 | D13: =+SUM(I13,K13,M13,O13,Q13,S13,U13,W13) -> 3 | E13: =SUM($C$11:C13) -> 0.37037037 | F13: =SUM($D$11:D13) -> 6 | G13: =IF(COUNT($D$11:D13)=0,"",F13/E13) -> 16.2 | H13: =IF(G13="","",IF(G13>=0.95,"En meta",IF(G13>=0.8,"Riesgo","Atrasado"))) -> En meta | I13: 3 | J13: =IF(I13="","",IF($I$9="","",IF($I$9=0,"",I13/$I$9))) -> 0.6 | L13: =IF(K13="","",IF($K$9="","",IF($K$9=0,"",K13/$K$9))) | N13: =IF(M13="","",IF($M$9="","",IF($M$9=0,"",M13/$M$9))) | P13: =IF(O13="","",IF($O$9="","",IF($O$9=0,"",O13/$O$9))) | R13: =IF(Q13="","",IF($Q$9="","",IF($Q$9=0,"",Q13/$Q$9))) | T13: =IF(S13="","",IF($S$9="","",IF($S$9=0,"",S13/$S$9))) | V13: =IF(U13="","",IF($U$9="","",IF($U$9=0,"",U13/$U$9))) | X13: =IF(W13="","",IF($W$9="","",IF($W$9=0,"",W13/$W$9)))
A14: 4 | B14: 46209 | C14: =$B$5/$B$8 -> 0.12345679 | D14: =+SUM(I14,K14,M14,O14,Q14,S14,U14,W14) -> 1 | E14: =SUM($C$11:C14) -> 0.49382716 | F14: =SUM($D$11:D14) -> 7 | G14: =IF(COUNT($D$11:D14)=0,"",F14/E14) -> 14.175 | H14: =IF(G14="","",IF(G14>=0.95,"En meta",IF(G14>=0.8,"Riesgo","Atrasado"))) -> En meta | J14: =IF(I14="","",IF($I$9="","",IF($I$9=0,"",I14/$I$9))) | L14: =IF(K14="","",IF($K$9="","",IF($K$9=0,"",K14/$K$9))) | N14: =IF(M14="","",IF($M$9="","",IF($M$9=0,"",M14/$M$9))) | P14: =IF(O14="","",IF($O$9="","",IF($O$9=0,"",O14/$O$9))) | Q14: 1 | R14: =IF(Q14="","",IF($Q$9="","",IF($Q$9=0,"",Q14/$Q$9))) -> 0.1 | T14: =IF(S14="","",IF($S$9="","",IF($S$9=0,"",S14/$S$9))) | V14: =IF(U14="","",IF($U$9="","",IF($U$9=0,"",U14/$U$9))) | X14: =IF(W14="","",IF($W$9="","",IF($W$9=0,"",W14/$W$9)))
A15: 5 | B15: 46216 | C15: =$B$5/$B$8 -> 0.12345679 | D15: =+SUM(I15,K15,M15,O15,Q15,S15,U15,W15) -> 0 | E15: =SUM($C$11:C15) -> 0.61728395 | F15: =SUM($D$11:D15) -> 7 | G15: =IF(COUNT($D$11:D15)=0,"",F15/E15) -> 11.34 | H15: =IF(G15="","",IF(G15>=0.95,"En meta",IF(G15>=0.8,"Riesgo","Atrasado"))) -> En meta | J15: =IF(I15="","",IF($I$9="","",IF($I$9=0,"",I15/$I$9))) | L15: =IF(K15="","",IF($K$9="","",IF($K$9=0,"",K15/$K$9))) | N15: =IF(M15="","",IF($M$9="","",IF($M$9=0,"",M15/$M$9))) | P15: =IF(O15="","",IF($O$9="","",IF($O$9=0,"",O15/$O$9))) | R15: =IF(Q15="","",IF($Q$9="","",IF($Q$9=0,"",Q15/$Q$9))) | T15: =IF(S15="","",IF($S$9="","",IF($S$9=0,"",S15/$S$9))) | V15: =IF(U15="","",IF($U$9="","",IF($U$9=0,"",U15/$U$9))) | X15: =IF(W15="","",IF($W$9="","",IF($W$9=0,"",W15/$W$9)))
A16: 6 | B16: 46223 | C16: =$B$5/$B$8 -> 0.12345679 | D16: =+SUM(I16,K16,M16,O16,Q16,S16,U16,W16) -> 1 | E16: =SUM($C$11:C16) -> 0.74074074 | F16: =SUM($D$11:D16) -> 8 | G16: =IF(COUNT($D$11:D16)=0,"",F16/E16) -> 10.8 | H16: =IF(G16="","",IF(G16>=0.95,"En meta",IF(G16>=0.8,"Riesgo","Atrasado"))) -> En meta | J16: =IF(I16="","",IF($I$9="","",IF($I$9=0,"",I16/$I$9))) | L16: =IF(K16="","",IF($K$9="","",IF($K$9=0,"",K16/$K$9))) | N16: =IF(M16="","",IF($M$9="","",IF($M$9=0,"",M16/$M$9))) | P16: =IF(O16="","",IF($O$9="","",IF($O$9=0,"",O16/$O$9))) | Q16: 1 | R16: =IF(Q16="","",IF($Q$9="","",IF($Q$9=0,"",Q16/$Q$9))) -> 0.1 | T16: =IF(S16="","",IF($S$9="","",IF($S$9=0,"",S16/$S$9))) | V16: =IF(U16="","",IF($U$9="","",IF($U$9=0,"",U16/$U$9))) | X16: =IF(W16="","",IF($W$9="","",IF($W$9=0,"",W16/$W$9)))
A17: 7 | B17: 46230 | C17: =$B$5/$B$8 -> 0.12345679 | D17: =+SUM(I17,K17,M17,O17,Q17,S17,U17,W17) -> 0 | E17: =SUM($C$11:C17) -> 0.86419753 | F17: =SUM($D$11:D17) -> 8 | G17: =IF(COUNT($D$11:D17)=0,"",F17/E17) -> 9.2571429 | H17: =IF(G17="","",IF(G17>=0.95,"En meta",IF(G17>=0.8,"Riesgo","Atrasado"))) -> En meta | J17: =IF(I17="","",IF($I$9="","",IF($I$9=0,"",I17/$I$9))) | L17: =IF(K17="","",IF($K$9="","",IF($K$9=0,"",K17/$K$9))) | N17: =IF(M17="","",IF($M$9="","",IF($M$9=0,"",M17/$M$9))) | P17: =IF(O17="","",IF($O$9="","",IF($O$9=0,"",O17/$O$9))) | R17: =IF(Q17="","",IF($Q$9="","",IF($Q$9=0,"",Q17/$Q$9))) | T17: =IF(S17="","",IF($S$9="","",IF($S$9=0,"",S17/$S$9))) | V17: =IF(U17="","",IF($U$9="","",IF($U$9=0,"",U17/$U$9))) | X17: =IF(W17="","",IF($W$9="","",IF($W$9=0,"",W17/$W$9)))
A18: 8 | B18: 46237 | C18: =$B$5/$B$8 -> 0.12345679 | D18: =+SUM(I18,K18,M18,O18,Q18,S18,U18,W18) -> 1 | E18: =SUM($C$11:C18) -> 0.98765432 | F18: =SUM($D$11:D18) -> 9 | G18: =IF(COUNT($D$11:D18)=0,"",F18/E18) -> 9.1125 | H18: =IF(G18="","",IF(G18>=0.95,"En meta",IF(G18>=0.8,"Riesgo","Atrasado"))) -> En meta | J18: =IF(I18="","",IF($I$9="","",IF($I$9=0,"",I18/$I$9))) | L18: =IF(K18="","",IF($K$9="","",IF($K$9=0,"",K18/$K$9))) | N18: =IF(M18="","",IF($M$9="","",IF($M$9=0,"",M18/$M$9))) | P18: =IF(O18="","",IF($O$9="","",IF($O$9=0,"",O18/$O$9))) | Q18: 1 | R18: =IF(Q18="","",IF($Q$9="","",IF($Q$9=0,"",Q18/$Q$9))) -> 0.1 | T18: =IF(S18="","",IF($S$9="","",IF($S$9=0,"",S18/$S$9))) | V18: =IF(U18="","",IF($U$9="","",IF($U$9=0,"",U18/$U$9))) | X18: =IF(W18="","",IF($W$9="","",IF($W$9=0,"",W18/$W$9)))
A19: 9 | B19: 46244 | C19: =$B$5/$B$8 -> 0.12345679 | D19: =+SUM(I19,K19,M19,O19,Q19,S19,U19,W19) -> 0 | E19: =SUM($C$11:C19) -> 1.1111111 | F19: =SUM($D$11:D19) -> 9 | G19: =IF(COUNT($D$11:D19)=0,"",F19/E19) -> 8.1 | H19: =IF(G19="","",IF(G19>=0.95,"En meta",IF(G19>=0.8,"Riesgo","Atrasado"))) -> En meta | J19: =IF(I19="","",IF($I$9="","",IF($I$9=0,"",I19/$I$9))) | L19: =IF(K19="","",IF($K$9="","",IF($K$9=0,"",K19/$K$9))) | N19: =IF(M19="","",IF($M$9="","",IF($M$9=0,"",M19/$M$9))) | P19: =IF(O19="","",IF($O$9="","",IF($O$9=0,"",O19/$O$9))) | R19: =IF(Q19="","",IF($Q$9="","",IF($Q$9=0,"",Q19/$Q$9))) | T19: =IF(S19="","",IF($S$9="","",IF($S$9=0,"",S19/$S$9))) | V19: =IF(U19="","",IF($U$9="","",IF($U$9=0,"",U19/$U$9))) | X19: =IF(W19="","",IF($W$9="","",IF($W$9=0,"",W19/$W$9)))
A20: 10 | B20: 46251 | C20: =$B$5/$B$8 -> 0.12345679 | E20: =SUM($C$11:C20) -> 1.2345679 | F20: =SUM($D$11:D20) -> 9 | G20: =IF(COUNT($D$11:D20)=0,"",F20/E20) -> 7.29 | H20: =IF(G20="","",IF(G20>=0.95,"En meta",IF(G20>=0.8,"Riesgo","Atrasado"))) -> En meta | J20: =IF(I20="","",IF($I$9="","",IF($I$9=0,"",I20/$I$9))) | L20: =IF(K20="","",IF($K$9="","",IF($K$9=0,"",K20/$K$9))) | N20: =IF(M20="","",IF($M$9="","",IF($M$9=0,"",M20/$M$9))) | P20: =IF(O20="","",IF($O$9="","",IF($O$9=0,"",O20/$O$9))) | R20: =IF(Q20="","",IF($Q$9="","",IF($Q$9=0,"",Q20/$Q$9))) | T20: =IF(S20="","",IF($S$9="","",IF($S$9=0,"",S20/$S$9))) | V20: =IF(U20="","",IF($U$9="","",IF($U$9=0,"",U20/$U$9))) | X20: =IF(W20="","",IF($W$9="","",IF($W$9=0,"",W20/$W$9)))
A21: 11 | B21: 46258 | C21: =$B$5/$B$8 -> 0.12345679 | E21: =SUM($C$11:C21) -> 1.3580247 | F21: =SUM($D$11:D21) -> 9 | G21: =IF(COUNT($D$11:D21)=0,"",F21/E21) -> 6.6272727 | H21: =IF(G21="","",IF(G21>=0.95,"En meta",IF(G21>=0.8,"Riesgo","Atrasado"))) -> En meta | J21: =IF(I21="","",IF($I$9="","",IF($I$9=0,"",I21/$I$9))) | L21: =IF(K21="","",IF($K$9="","",IF($K$9=0,"",K21/$K$9))) | N21: =IF(M21="","",IF($M$9="","",IF($M$9=0,"",M21/$M$9))) | P21: =IF(O21="","",IF($O$9="","",IF($O$9=0,"",O21/$O$9))) | R21: =IF(Q21="","",IF($Q$9="","",IF($Q$9=0,"",Q21/$Q$9))) | T21: =IF(S21="","",IF($S$9="","",IF($S$9=0,"",S21/$S$9))) | V21: =IF(U21="","",IF($U$9="","",IF($U$9=0,"",U21/$U$9))) | X21: =IF(W21="","",IF($W$9="","",IF($W$9=0,"",W21/$W$9)))
A22: 12 | B22: 46265 | C22: =$B$5/$B$8 -> 0.12345679 | E22: =SUM($C$11:C22) -> 1.4814815 | F22: =SUM($D$11:D22) -> 9 | G22: =IF(COUNT($D$11:D22)=0,"",F22/E22) -> 6.075 | H22: =IF(G22="","",IF(G22>=0.95,"En meta",IF(G22>=0.8,"Riesgo","Atrasado"))) -> En meta | J22: =IF(I22="","",IF($I$9="","",IF($I$9=0,"",I22/$I$9))) | L22: =IF(K22="","",IF($K$9="","",IF($K$9=0,"",K22/$K$9))) | N22: =IF(M22="","",IF($M$9="","",IF($M$9=0,"",M22/$M$9))) | P22: =IF(O22="","",IF($O$9="","",IF($O$9=0,"",O22/$O$9))) | R22: =IF(Q22="","",IF($Q$9="","",IF($Q$9=0,"",Q22/$Q$9))) | T22: =IF(S22="","",IF($S$9="","",IF($S$9=0,"",S22/$S$9))) | V22: =IF(U22="","",IF($U$9="","",IF($U$9=0,"",U22/$U$9))) | X22: =IF(W22="","",IF($W$9="","",IF($W$9=0,"",W22/$W$9)))
A23: 13 | B23: 46272 | C23: =$B$5/$B$8 -> 0.12345679 | E23: =SUM($C$11:C23) -> 1.6049383 | F23: =SUM($D$11:D23) -> 9 | G23: =IF(COUNT($D$11:D23)=0,"",F23/E23) -> 5.6076923 | H23: =IF(G23="","",IF(G23>=0.95,"En meta",IF(G23>=0.8,"Riesgo","Atrasado"))) -> En meta | J23: =IF(I23="","",IF($I$9="","",IF($I$9=0,"",I23/$I$9))) | L23: =IF(K23="","",IF($K$9="","",IF($K$9=0,"",K23/$K$9))) | N23: =IF(M23="","",IF($M$9="","",IF($M$9=0,"",M23/$M$9))) | P23: =IF(O23="","",IF($O$9="","",IF($O$9=0,"",O23/$O$9))) | R23: =IF(Q23="","",IF($Q$9="","",IF($Q$9=0,"",Q23/$Q$9))) | T23: =IF(S23="","",IF($S$9="","",IF($S$9=0,"",S23/$S$9))) | V23: =IF(U23="","",IF($U$9="","",IF($U$9=0,"",U23/$U$9))) | X23: =IF(W23="","",IF($W$9="","",IF($W$9=0,"",W23/$W$9)))
A24: 14 | B24: 46279 | C24: =$B$5/$B$8 -> 0.12345679 | E24: =SUM($C$11:C24) -> 1.7283951 | F24: =SUM($D$11:D24) -> 9 | G24: =IF(COUNT($D$11:D24)=0,"",F24/E24) -> 5.2071429 | H24: =IF(G24="","",IF(G24>=0.95,"En meta",IF(G24>=0.8,"Riesgo","Atrasado"))) -> En meta | J24: =IF(I24="","",IF($I$9="","",IF($I$9=0,"",I24/$I$9))) | L24: =IF(K24="","",IF($K$9="","",IF($K$9=0,"",K24/$K$9))) | N24: =IF(M24="","",IF($M$9="","",IF($M$9=0,"",M24/$M$9))) | P24: =IF(O24="","",IF($O$9="","",IF($O$9=0,"",O24/$O$9))) | R24: =IF(Q24="","",IF($Q$9="","",IF($Q$9=0,"",Q24/$Q$9))) | T24: =IF(S24="","",IF($S$9="","",IF($S$9=0,"",S24/$S$9))) | V24: =IF(U24="","",IF($U$9="","",IF($U$9=0,"",U24/$U$9))) | X24: =IF(W24="","",IF($W$9="","",IF($W$9=0,"",W24/$W$9)))
A25: 15 | B25: 46286 | C25: =$B$5/$B$8 -> 0.12345679 | E25: =SUM($C$11:C25) -> 1.8518519 | F25: =SUM($D$11:D25) -> 9 | G25: =IF(COUNT($D$11:D25)=0,"",F25/E25) -> 4.86 | H25: =IF(G25="","",IF(G25>=0.95,"En meta",IF(G25>=0.8,"Riesgo","Atrasado"))) -> En meta | J25: =IF(I25="","",IF($I$9="","",IF($I$9=0,"",I25/$I$9))) | L25: =IF(K25="","",IF($K$9="","",IF($K$9=0,"",K25/$K$9))) | N25: =IF(M25="","",IF($M$9="","",IF($M$9=0,"",M25/$M$9))) | P25: =IF(O25="","",IF($O$9="","",IF($O$9=0,"",O25/$O$9))) | R25: =IF(Q25="","",IF($Q$9="","",IF($Q$9=0,"",Q25/$Q$9))) | T25: =IF(S25="","",IF($S$9="","",IF($S$9=0,"",S25/$S$9))) | V25: =IF(U25="","",IF($U$9="","",IF($U$9=0,"",U25/$U$9))) | X25: =IF(W25="","",IF($W$9="","",IF($W$9=0,"",W25/$W$9)))
A26: 16 | B26: 46293 | C26: =$B$5/$B$8 -> 0.12345679 | E26: =SUM($C$11:C26) -> 1.9753086 | F26: =SUM($D$11:D26) -> 9 | G26: =IF(COUNT($D$11:D26)=0,"",F26/E26) -> 4.55625 | H26: =IF(G26="","",IF(G26>=0.95,"En meta",IF(G26>=0.8,"Riesgo","Atrasado"))) -> En meta | J26: =IF(I26="","",IF($I$9="","",IF($I$9=0,"",I26/$I$9))) | L26: =IF(K26="","",IF($K$9="","",IF($K$9=0,"",K26/$K$9))) | N26: =IF(M26="","",IF($M$9="","",IF($M$9=0,"",M26/$M$9))) | P26: =IF(O26="","",IF($O$9="","",IF($O$9=0,"",O26/$O$9))) | R26: =IF(Q26="","",IF($Q$9="","",IF($Q$9=0,"",Q26/$Q$9))) | T26: =IF(S26="","",IF($S$9="","",IF($S$9=0,"",S26/$S$9))) | V26: =IF(U26="","",IF($U$9="","",IF($U$9=0,"",U26/$U$9))) | X26: =IF(W26="","",IF($W$9="","",IF($W$9=0,"",W26/$W$9)))
A27: 17 | B27: 46300 | C27: =$B$5/$B$8 -> 0.12345679 | E27: =SUM($C$11:C27) -> 2.0987654 | F27: =SUM($D$11:D27) -> 9 | G27: =IF(COUNT($D$11:D27)=0,"",F27/E27) -> 4.2882353 | H27: =IF(G27="","",IF(G27>=0.95,"En meta",IF(G27>=0.8,"Riesgo","Atrasado"))) -> En meta | J27: =IF(I27="","",IF($I$9="","",IF($I$9=0,"",I27/$I$9))) | L27: =IF(K27="","",IF($K$9="","",IF($K$9=0,"",K27/$K$9))) | N27: =IF(M27="","",IF($M$9="","",IF($M$9=0,"",M27/$M$9))) | P27: =IF(O27="","",IF($O$9="","",IF($O$9=0,"",O27/$O$9))) | R27: =IF(Q27="","",IF($Q$9="","",IF($Q$9=0,"",Q27/$Q$9))) | T27: =IF(S27="","",IF($S$9="","",IF($S$9=0,"",S27/$S$9))) | V27: =IF(U27="","",IF($U$9="","",IF($U$9=0,"",U27/$U$9))) | X27: =IF(W27="","",IF($W$9="","",IF($W$9=0,"",W27/$W$9)))
A28: 18 | B28: 46307 | C28: =$B$5/$B$8 -> 0.12345679 | E28: =SUM($C$11:C28) -> 2.2222222 | F28: =SUM($D$11:D28) -> 9 | G28: =IF(COUNT($D$11:D28)=0,"",F28/E28) -> 4.05 | H28: =IF(G28="","",IF(G28>=0.95,"En meta",IF(G28>=0.8,"Riesgo","Atrasado"))) -> En meta | J28: =IF(I28="","",IF($I$9="","",IF($I$9=0,"",I28/$I$9))) | L28: =IF(K28="","",IF($K$9="","",IF($K$9=0,"",K28/$K$9))) | N28: =IF(M28="","",IF($M$9="","",IF($M$9=0,"",M28/$M$9))) | P28: =IF(O28="","",IF($O$9="","",IF($O$9=0,"",O28/$O$9))) | R28: =IF(Q28="","",IF($Q$9="","",IF($Q$9=0,"",Q28/$Q$9))) | T28: =IF(S28="","",IF($S$9="","",IF($S$9=0,"",S28/$S$9))) | V28: =IF(U28="","",IF($U$9="","",IF($U$9=0,"",U28/$U$9))) | X28: =IF(W28="","",IF($W$9="","",IF($W$9=0,"",W28/$W$9)))
A29: 19 | B29: 46314 | C29: =$B$5/$B$8 -> 0.12345679 | E29: =SUM($C$11:C29) -> 2.345679 | F29: =SUM($D$11:D29) -> 9 | G29: =IF(COUNT($D$11:D29)=0,"",F29/E29) -> 3.8368421 | H29: =IF(G29="","",IF(G29>=0.95,"En meta",IF(G29>=0.8,"Riesgo","Atrasado"))) -> En meta | J29: =IF(I29="","",IF($I$9="","",IF($I$9=0,"",I29/$I$9))) | L29: =IF(K29="","",IF($K$9="","",IF($K$9=0,"",K29/$K$9))) | N29: =IF(M29="","",IF($M$9="","",IF($M$9=0,"",M29/$M$9))) | P29: =IF(O29="","",IF($O$9="","",IF($O$9=0,"",O29/$O$9))) | R29: =IF(Q29="","",IF($Q$9="","",IF($Q$9=0,"",Q29/$Q$9))) | T29: =IF(S29="","",IF($S$9="","",IF($S$9=0,"",S29/$S$9))) | V29: =IF(U29="","",IF($U$9="","",IF($U$9=0,"",U29/$U$9))) | X29: =IF(W29="","",IF($W$9="","",IF($W$9=0,"",W29/$W$9)))
A30: 20 | B30: 46321 | C30: =$B$5/$B$8 -> 0.12345679 | E30: =SUM($C$11:C30) -> 2.4691358 | F30: =SUM($D$11:D30) -> 9 | G30: =IF(COUNT($D$11:D30)=0,"",F30/E30) -> 3.645 | H30: =IF(G30="","",IF(G30>=0.95,"En meta",IF(G30>=0.8,"Riesgo","Atrasado"))) -> En meta | J30: =IF(I30="","",IF($I$9="","",IF($I$9=0,"",I30/$I$9))) | L30: =IF(K30="","",IF($K$9="","",IF($K$9=0,"",K30/$K$9))) | N30: =IF(M30="","",IF($M$9="","",IF($M$9=0,"",M30/$M$9))) | P30: =IF(O30="","",IF($O$9="","",IF($O$9=0,"",O30/$O$9))) | R30: =IF(Q30="","",IF($Q$9="","",IF($Q$9=0,"",Q30/$Q$9))) | T30: =IF(S30="","",IF($S$9="","",IF($S$9=0,"",S30/$S$9))) | V30: =IF(U30="","",IF($U$9="","",IF($U$9=0,"",U30/$U$9))) | X30: =IF(W30="","",IF($W$9="","",IF($W$9=0,"",W30/$W$9)))
A31: 21 | B31: 46328 | C31: =$B$5/$B$8 -> 0.12345679 | E31: =SUM($C$11:C31) -> 2.5925926 | F31: =SUM($D$11:D31) -> 9 | G31: =IF(COUNT($D$11:D31)=0,"",F31/E31) -> 3.4714286 | H31: =IF(G31="","",IF(G31>=0.95,"En meta",IF(G31>=0.8,"Riesgo","Atrasado"))) -> En meta | J31: =IF(I31="","",IF($I$9="","",IF($I$9=0,"",I31/$I$9))) | L31: =IF(K31="","",IF($K$9="","",IF($K$9=0,"",K31/$K$9))) | N31: =IF(M31="","",IF($M$9="","",IF($M$9=0,"",M31/$M$9))) | P31: =IF(O31="","",IF($O$9="","",IF($O$9=0,"",O31/$O$9))) | R31: =IF(Q31="","",IF($Q$9="","",IF($Q$9=0,"",Q31/$Q$9))) | T31: =IF(S31="","",IF($S$9="","",IF($S$9=0,"",S31/$S$9))) | V31: =IF(U31="","",IF($U$9="","",IF($U$9=0,"",U31/$U$9))) | X31: =IF(W31="","",IF($W$9="","",IF($W$9=0,"",W31/$W$9)))
... A91: 81 | B91: 46748 | C91: =$B$5/$B$8 -> 0.12345679 | E91: =SUM($C$11:C91) -> 10 | F91: =SUM($D$11:D91) -> 9 | G91: =IF(COUNT($D$11:D91)=0,"",F91/E91) -> 0.9 | H91: =IF(G91="","",IF(G91>=0.95,"En meta",IF(G91>=0.8,"Riesgo","Atrasado"))) -> Riesgo | J91: =IF(I91="","",IF($I$9="","",IF($I$9=0,"",I91/$I$9))) | L91: =IF(K91="","",IF($K$9="","",IF($K$9=0,"",K91/$K$9))) | N91: =IF(M91="","",IF($M$9="","",IF($M$9=0,"",M91/$M$9))) | P91: =IF(O91="","",IF($O$9="","",IF($O$9=0,"",O91/$O$9))) | R91: =IF(Q91="","",IF($Q$9="","",IF($Q$9=0,"",Q91/$Q$9))) | T91: =IF(S91="","",IF($S$9="","",IF($S$9=0,"",S91/$S$9))) | V91: =IF(U91="","",IF($U$9="","",IF($U$9=0,"",U91/$U$9))) | X91: =IF(W91="","",IF($W$9="","",IF($W$9=0,"",W91/$W$9)))

Sheet 4. Entregas 100%
A1: WIG 4 — Cumplir el 100% de entregas y colocaciones en tiempo y forma
A2: Indicador lag: | B2: % de colocaciones y entregas de la semana realizadas en tiempo y forma.
A3: De X a Y: | B3: Sostener 100% de cumplimiento semanal durante todo el periodo.
A4: Dueño: | B4: Por asignar | D4: Equipo: | E4: Finanzas
A5: Meta: | B5: 1 | D5: Inicio: | E5: 46188 | G5: Fin: | H5: 46748
A6: Leads: | B6: Hasta 8 indicadores predictivos a la derecha. L1–L2 = apuesta principal del equipo; L3–L8 = indicadores de apoyo. Nombre (fila 8) y meta semanal (fila 9) editables en azul.
A8: Periodos: | B8: =COUNT(A11:A91) -> 81 | H8: Lead → | I8: L1. % entregas programadas con checklist completo | K8: L2. Riesgos de entrega escalados ≥1 semana antes | M8: L3. % órdenes de compra liberadas a tiempo | O8: L4. % inventario confirmado ≥5 días antes | Q8: L5. Coordinaciones logísticas confirmadas | S8: L6. % facturas emitidas ≤48h tras la entrega | U8: (Disponible) | W8: (Disponible)
A9: Celdas azules = se digitan cada lunes. Celdas negras = fórmulas, no tocar. | H9: Meta → | I9: 1 | K9: 1 | M9: 1 | O9: 1 | Q9: 5 | S9: 1
A10: # | B10: Semana | C10: Meta | D10: Real | G10: Brecha vs meta | H10: Estado | I10: Real | J10: % | K10: Real | L10: % | M10: Real | N10: % | O10: Real | P10: % | Q10: Real | R10: % | S10: Real | T10: % | U10: Real | V10: % | W10: Real | X10: %
A11: 1 | B11: 46188 | C11: =$B$5 -> 1 | G11: =IF(D11="","",D11-C11) | H11: =IF(D11="","",IF(D11>=C11,"En meta",IF(D11>=C11-0.05,"Riesgo","Atrasado"))) | J11: =IF(I11="","",IF($I$9="","",IF($I$9=0,"",I11/$I$9))) | L11: =IF(K11="","",IF($K$9="","",IF($K$9=0,"",K11/$K$9))) | N11: =IF(M11="","",IF($M$9="","",IF($M$9=0,"",M11/$M$9))) | P11: =IF(O11="","",IF($O$9="","",IF($O$9=0,"",O11/$O$9))) | R11: =IF(Q11="","",IF($Q$9="","",IF($Q$9=0,"",Q11/$Q$9))) | T11: =IF(S11="","",IF($S$9="","",IF($S$9=0,"",S11/$S$9))) | V11: =IF(U11="","",IF($U$9="","",IF($U$9=0,"",U11/$U$9))) | X11: =IF(W11="","",IF($W$9="","",IF($W$9=0,"",W11/$W$9)))
A12: 2 | B12: 46195 | C12: =$B$5 -> 1 | G12: =IF(D12="","",D12-C12) | H12: =IF(D12="","",IF(D12>=C12,"En meta",IF(D12>=C12-0.05,"Riesgo","Atrasado"))) | J12: =IF(I12="","",IF($I$9="","",IF($I$9=0,"",I12/$I$9))) | L12: =IF(K12="","",IF($K$9="","",IF($K$9=0,"",K12/$K$9))) | N12: =IF(M12="","",IF($M$9="","",IF($M$9=0,"",M12/$M$9))) | P12: =IF(O12="","",IF($O$9="","",IF($O$9=0,"",O12/$O$9))) | R12: =IF(Q12="","",IF($Q$9="","",IF($Q$9=0,"",Q12/$Q$9))) | T12: =IF(S12="","",IF($S$9="","",IF($S$9=0,"",S12/$S$9))) | V12: =IF(U12="","",IF($U$9="","",IF($U$9=0,"",U12/$U$9))) | X12: =IF(W12="","",IF($W$9="","",IF($W$9=0,"",W12/$W$9)))
A13: 3 | B13: 46202 | C13: =$B$5 -> 1 | G13: =IF(D13="","",D13-C13) | H13: =IF(D13="","",IF(D13>=C13,"En meta",IF(D13>=C13-0.05,"Riesgo","Atrasado"))) | J13: =IF(I13="","",IF($I$9="","",IF($I$9=0,"",I13/$I$9))) | L13: =IF(K13="","",IF($K$9="","",IF($K$9=0,"",K13/$K$9))) | N13: =IF(M13="","",IF($M$9="","",IF($M$9=0,"",M13/$M$9))) | P13: =IF(O13="","",IF($O$9="","",IF($O$9=0,"",O13/$O$9))) | R13: =IF(Q13="","",IF($Q$9="","",IF($Q$9=0,"",Q13/$Q$9))) | T13: =IF(S13="","",IF($S$9="","",IF($S$9=0,"",S13/$S$9))) | V13: =IF(U13="","",IF($U$9="","",IF($U$9=0,"",U13/$U$9))) | X13: =IF(W13="","",IF($W$9="","",IF($W$9=0,"",W13/$W$9)))
A14: 4 | B14: 46209 | C14: =$B$5 -> 1 | G14: =IF(D14="","",D14-C14) | H14: =IF(D14="","",IF(D14>=C14,"En meta",IF(D14>=C14-0.05,"Riesgo","Atrasado"))) | J14: =IF(I14="","",IF($I$9="","",IF($I$9=0,"",I14/$I$9))) | L14: =IF(K14="","",IF($K$9="","",IF($K$9=0,"",K14/$K$9))) | N14: =IF(M14="","",IF($M$9="","",IF($M$9=0,"",M14/$M$9))) | P14: =IF(O14="","",IF($O$9="","",IF($O$9=0,"",O14/$O$9))) | R14: =IF(Q14="","",IF($Q$9="","",IF($Q$9=0,"",Q14/$Q$9))) | T14: =IF(S14="","",IF($S$9="","",IF($S$9=0,"",S14/$S$9))) | V14: =IF(U14="","",IF($U$9="","",IF($U$9=0,"",U14/$U$9))) | X14: =IF(W14="","",IF($W$9="","",IF($W$9=0,"",W14/$W$9)))
A15: 5 | B15: 46216 | C15: =$B$5 -> 1 | G15: =IF(D15="","",D15-C15) | H15: =IF(D15="","",IF(D15>=C15,"En meta",IF(D15>=C15-0.05,"Riesgo","Atrasado"))) | J15: =IF(I15="","",IF($I$9="","",IF($I$9=0,"",I15/$I$9))) | L15: =IF(K15="","",IF($K$9="","",IF($K$9=0,"",K15/$K$9))) | N15: =IF(M15="","",IF($M$9="","",IF($M$9=0,"",M15/$M$9))) | P15: =IF(O15="","",IF($O$9="","",IF($O$9=0,"",O15/$O$9))) | R15: =IF(Q15="","",IF($Q$9="","",IF($Q$9=0,"",Q15/$Q$9))) | T15: =IF(S15="","",IF($S$9="","",IF($S$9=0,"",S15/$S$9))) | V15: =IF(U15="","",IF($U$9="","",IF($U$9=0,"",U15/$U$9))) | X15: =IF(W15="","",IF($W$9="","",IF($W$9=0,"",W15/$W$9)))
A16: 6 | B16: 46223 | C16: =$B$5 -> 1 | G16: =IF(D16="","",D16-C16) | H16: =IF(D16="","",IF(D16>=C16,"En meta",IF(D16>=C16-0.05,"Riesgo","Atrasado"))) | J16: =IF(I16="","",IF($I$9="","",IF($I$9=0,"",I16/$I$9))) | L16: =IF(K16="","",IF($K$9="","",IF($K$9=0,"",K16/$K$9))) | N16: =IF(M16="","",IF($M$9="","",IF($M$9=0,"",M16/$M$9))) | P16: =IF(O16="","",IF($O$9="","",IF($O$9=0,"",O16/$O$9))) | R16: =IF(Q16="","",IF($Q$9="","",IF($Q$9=0,"",Q16/$Q$9))) | T16: =IF(S16="","",IF($S$9="","",IF($S$9=0,"",S16/$S$9))) | V16: =IF(U16="","",IF($U$9="","",IF($U$9=0,"",U16/$U$9))) | X16: =IF(W16="","",IF($W$9="","",IF($W$9=0,"",W16/$W$9)))
A17: 7 | B17: 46230 | C17: =$B$5 -> 1 | G17: =IF(D17="","",D17-C17) | H17: =IF(D17="","",IF(D17>=C17,"En meta",IF(D17>=C17-0.05,"Riesgo","Atrasado"))) | J17: =IF(I17="","",IF($I$9="","",IF($I$9=0,"",I17/$I$9))) | L17: =IF(K17="","",IF($K$9="","",IF($K$9=0,"",K17/$K$9))) | N17: =IF(M17="","",IF($M$9="","",IF($M$9=0,"",M17/$M$9))) | P17: =IF(O17="","",IF($O$9="","",IF($O$9=0,"",O17/$O$9))) | R17: =IF(Q17="","",IF($Q$9="","",IF($Q$9=0,"",Q17/$Q$9))) | T17: =IF(S17="","",IF($S$9="","",IF($S$9=0,"",S17/$S$9))) | V17: =IF(U17="","",IF($U$9="","",IF($U$9=0,"",U17/$U$9))) | X17: =IF(W17="","",IF($W$9="","",IF($W$9=0,"",W17/$W$9)))
A18: 8 | B18: 46237 | C18: =$B$5 -> 1 | G18: =IF(D18="","",D18-C18) | H18: =IF(D18="","",IF(D18>=C18,"En meta",IF(D18>=C18-0.05,"Riesgo","Atrasado"))) | J18: =IF(I18="","",IF($I$9="","",IF($I$9=0,"",I18/$I$9))) | L18: =IF(K18="","",IF($K$9="","",IF($K$9=0,"",K18/$K$9))) | N18: =IF(M18="","",IF($M$9="","",IF($M$9=0,"",M18/$M$9))) | P18: =IF(O18="","",IF($O$9="","",IF($O$9=0,"",O18/$O$9))) | R18: =IF(Q18="","",IF($Q$9="","",IF($Q$9=0,"",Q18/$Q$9))) | T18: =IF(S18="","",IF($S$9="","",IF($S$9=0,"",S18/$S$9))) | V18: =IF(U18="","",IF($U$9="","",IF($U$9=0,"",U18/$U$9))) | X18: =IF(W18="","",IF($W$9="","",IF($W$9=0,"",W18/$W$9)))
A19: 9 | B19: 46244 | C19: =$B$5 -> 1 | G19: =IF(D19="","",D19-C19) | H19: =IF(D19="","",IF(D19>=C19,"En meta",IF(D19>=C19-0.05,"Riesgo","Atrasado"))) | J19: =IF(I19="","",IF($I$9="","",IF($I$9=0,"",I19/$I$9))) | L19: =IF(K19="","",IF($K$9="","",IF($K$9=0,"",K19/$K$9))) | N19: =IF(M19="","",IF($M$9="","",IF($M$9=0,"",M19/$M$9))) | P19: =IF(O19="","",IF($O$9="","",IF($O$9=0,"",O19/$O$9))) | R19: =IF(Q19="","",IF($Q$9="","",IF($Q$9=0,"",Q19/$Q$9))) | T19: =IF(S19="","",IF($S$9="","",IF($S$9=0,"",S19/$S$9))) | V19: =IF(U19="","",IF($U$9="","",IF($U$9=0,"",U19/$U$9))) | X19: =IF(W19="","",IF($W$9="","",IF($W$9=0,"",W19/$W$9)))
A20: 10 | B20: 46251 | C20: =$B$5 -> 1 | G20: =IF(D20="","",D20-C20) | H20: =IF(D20="","",IF(D20>=C20,"En meta",IF(D20>=C20-0.05,"Riesgo","Atrasado"))) | J20: =IF(I20="","",IF($I$9="","",IF($I$9=0,"",I20/$I$9))) | L20: =IF(K20="","",IF($K$9="","",IF($K$9=0,"",K20/$K$9))) | N20: =IF(M20="","",IF($M$9="","",IF($M$9=0,"",M20/$M$9))) | P20: =IF(O20="","",IF($O$9="","",IF($O$9=0,"",O20/$O$9))) | R20: =IF(Q20="","",IF($Q$9="","",IF($Q$9=0,"",Q20/$Q$9))) | T20: =IF(S20="","",IF($S$9="","",IF($S$9=0,"",S20/$S$9))) | V20: =IF(U20="","",IF($U$9="","",IF($U$9=0,"",U20/$U$9))) | X20: =IF(W20="","",IF($W$9="","",IF($W$9=0,"",W20/$W$9)))
A21: 11 | B21: 46258 | C21: =$B$5 -> 1 | G21: =IF(D21="","",D21-C21) | H21: =IF(D21="","",IF(D21>=C21,"En meta",IF(D21>=C21-0.05,"Riesgo","Atrasado"))) | J21: =IF(I21="","",IF($I$9="","",IF($I$9=0,"",I21/$I$9))) | L21: =IF(K21="","",IF($K$9="","",IF($K$9=0,"",K21/$K$9))) | N21: =IF(M21="","",IF($M$9="","",IF($M$9=0,"",M21/$M$9))) | P21: =IF(O21="","",IF($O$9="","",IF($O$9=0,"",O21/$O$9))) | R21: =IF(Q21="","",IF($Q$9="","",IF($Q$9=0,"",Q21/$Q$9))) | T21: =IF(S21="","",IF($S$9="","",IF($S$9=0,"",S21/$S$9))) | V21: =IF(U21="","",IF($U$9="","",IF($U$9=0,"",U21/$U$9))) | X21: =IF(W21="","",IF($W$9="","",IF($W$9=0,"",W21/$W$9)))
A22: 12 | B22: 46265 | C22: =$B$5 -> 1 | G22: =IF(D22="","",D22-C22) | H22: =IF(D22="","",IF(D22>=C22,"En meta",IF(D22>=C22-0.05,"Riesgo","Atrasado"))) | J22: =IF(I22="","",IF($I$9="","",IF($I$9=0,"",I22/$I$9))) | L22: =IF(K22="","",IF($K$9="","",IF($K$9=0,"",K22/$K$9))) | N22: =IF(M22="","",IF($M$9="","",IF($M$9=0,"",M22/$M$9))) | P22: =IF(O22="","",IF($O$9="","",IF($O$9=0,"",O22/$O$9))) | R22: =IF(Q22="","",IF($Q$9="","",IF($Q$9=0,"",Q22/$Q$9))) | T22: =IF(S22="","",IF($S$9="","",IF($S$9=0,"",S22/$S$9))) | V22: =IF(U22="","",IF($U$9="","",IF($U$9=0,"",U22/$U$9))) | X22: =IF(W22="","",IF($W$9="","",IF($W$9=0,"",W22/$W$9)))
... A91: 81 | B91: 46748 | C91: =$B$5 -> 1 | G91: =IF(D91="","",D91-C91) | H91: =IF(D91="","",IF(D91>=C91,"En meta",IF(D91>=C91-0.05,"Riesgo","Atrasado"))) | J91: =IF(I91="","",IF($I$9="","",IF($I$9=0,"",I91/$I$9))) | L91: =IF(K91="","",IF($K$9="","",IF($K$9=0,"",K91/$K$9))) | N91: =IF(M91="","",IF($M$9="","",IF($M$9=0,"",M91/$M$9))) | P91: =IF(O91="","",IF($O$9="","",IF($O$9=0,"",O91/$O$9))) | R91: =IF(Q91="","",IF($Q$9="","",IF($Q$9=0,"",Q91/$Q$9))) | T91: =IF(S91="","",IF($S$9="","",IF($S$9=0,"",S91/$S$9))) | V91: =IF(U91="","",IF($U$9="","",IF($U$9=0,"",U91/$U$9))) | X91: =IF(W91="","",IF($W$9="","",IF($W$9=0,"",W91/$W$9)))

Sheet 5. MV Datacenter
A1: WIG 5 — Incrementar el MV de servicios basados en el DC GBM San Marcos en $20,000
A2: Indicador lag: | B2: MV nuevo firmado de servicios basados desde el datacenter (USD acumulado).
A3: De X a Y: | B3: De $0 a +$20,000 de MV incremental, antes del 31 de diciembre de 2027.
A4: Dueño: | B4: Por asignar | D4: Equipo: | E4: Pre-Sales, Del - DC
A5: Meta: | B5: 20000 | D5: Inicio: | E5: 46188 | G5: Fin: | H5: 46748
A6: Leads: | B6: Hasta 8 indicadores predictivos a la derecha. L1–L2 = apuesta principal del equipo; L3–L8 = indicadores de apoyo. Nombre (fila 8) y meta semanal (fila 9) editables en azul.
A8: Periodos: | B8: =COUNT(A11:A91) -> 81 | H8: Lead → | I8: L1. Propuestas de servicios DC presentadas | K8: L2. Workloads nuevos aprovisionados / migrados | M8: L3. Assessments de migración realizados | O8: L4. Opps DC activas en pipeline | Q8: L5. Clientes contactados con oferta DC | S8: L6. % capacidad DC documentada y actualizada | U8: (Disponible) | W8: (Disponible)
